2020-11-02 11:24:39,228 [INFO] download_dataset.py(line 159) Downloading structures from /home/katebrich/Documents/diplomka/GitHub/datasets/chen11.txt to /home/katebrich/Documents/diplomka/P2Rank/datasets/chen11_11_02 started...
2020-11-02 11:24:42,761 [DEBUG] download_dataset.py(line 110) 1/241: 2nw8 A downloaded
2020-11-02 11:24:43,141 [DEBUG] download_dataset.py(line 110) 2/241: 1v7w A downloaded
2020-11-02 11:24:44,026 [DEBUG] download_dataset.py(line 110) 3/241: 1d7b A downloaded
2020-11-02 11:24:45,622 [DEBUG] download_dataset.py(line 110) 4/241: 2vbu A downloaded
2020-11-02 11:24:47,111 [DEBUG] download_dataset.py(line 110) 5/241: 2i02 A downloaded
2020-11-02 11:24:46,578 [ERROR] download_dataset.py(line 98) Error while downloading 1uh4 A: HTTP Error 502: Bad Gateway
Traceback (most recent call last):
  File "./pythonScripts/download_dataset.py", line 91, in download_structure
    get_FASTA(output_FASTA, pdb_id, chain_ids)
  File "./pythonScripts/download_dataset.py", line 72, in get_FASTA
    entity_id = get_entity_id(pdb_id, chain_id)  # todo mit udelany cache
  File "/home/katebrich/Documents/diplomka/GitHub/pythonScripts/helper.py", line 128, in get_entity_id
    response = str(restAPI_get(url))
  File "/home/katebrich/Documents/diplomka/GitHub/pythonScripts/helper.py", line 84, in restAPI_get
    with urllib.request.urlopen(req) as f:
  File "/home/katebrich/anaconda3/lib/python3.7/urllib/request.py", line 222, in urlopen
    return opener.open(url, data, timeout)
  File "/home/katebrich/anaconda3/lib/python3.7/urllib/request.py", line 531, in open
    response = meth(req, response)
  File "/home/katebrich/anaconda3/lib/python3.7/urllib/request.py", line 641, in http_response
    'http', request, response, code, msg, hdrs)
  File "/home/katebrich/anaconda3/lib/python3.7/urllib/request.py", line 569, in error
    return self._call_chain(*args)
  File "/home/katebrich/anaconda3/lib/python3.7/urllib/request.py", line 503, in _call_chain
    result = func(*args)
  File "/home/katebrich/anaconda3/lib/python3.7/urllib/request.py", line 649, in http_error_default
    raise HTTPError(req.full_url, code, msg, hdrs, fp)
urllib.error.HTTPError: HTTP Error 502: Bad Gateway
2020-11-02 11:24:46,577 [ERROR] download_dataset.py(line 98) Error while downloading 1dl2 A: HTTP Error 502: Bad Gateway
Traceback (most recent call last):
  File "./pythonScripts/download_dataset.py", line 91, in download_structure
    get_FASTA(output_FASTA, pdb_id, chain_ids)
  File "./pythonScripts/download_dataset.py", line 72, in get_FASTA
    entity_id = get_entity_id(pdb_id, chain_id)  # todo mit udelany cache
  File "/home/katebrich/Documents/diplomka/GitHub/pythonScripts/helper.py", line 128, in get_entity_id
    response = str(restAPI_get(url))
  File "/home/katebrich/Documents/diplomka/GitHub/pythonScripts/helper.py", line 84, in restAPI_get
    with urllib.request.urlopen(req) as f:
  File "/home/katebrich/anaconda3/lib/python3.7/urllib/request.py", line 222, in urlopen
    return opener.open(url, data, timeout)
  File "/home/katebrich/anaconda3/lib/python3.7/urllib/request.py", line 531, in open
    response = meth(req, response)
  File "/home/katebrich/anaconda3/lib/python3.7/urllib/request.py", line 641, in http_response
    'http', request, response, code, msg, hdrs)
  File "/home/katebrich/anaconda3/lib/python3.7/urllib/request.py", line 569, in error
    return self._call_chain(*args)
  File "/home/katebrich/anaconda3/lib/python3.7/urllib/request.py", line 503, in _call_chain
    result = func(*args)
  File "/home/katebrich/anaconda3/lib/python3.7/urllib/request.py", line 649, in http_error_default
    raise HTTPError(req.full_url, code, msg, hdrs, fp)
urllib.error.HTTPError: HTTP Error 502: Bad Gateway
2020-11-02 11:24:48,022 [ERROR] download_dataset.py(line 108) 6/241: 1uh4 A NOT DOWNLOADED !
2020-11-02 11:24:48,022 [ERROR] download_dataset.py(line 108) 7/241: 1dl2 A NOT DOWNLOADED !
2020-11-02 11:24:48,096 [DEBUG] download_dataset.py(line 110) 8/241: 1s69 A downloaded
2020-11-02 11:24:48,650 [DEBUG] download_dataset.py(line 110) 9/241: 1usf A downloaded
2020-11-02 11:24:49,288 [DEBUG] download_dataset.py(line 110) 10/241: 1do1 A downloaded
2020-11-02 11:24:49,369 [DEBUG] download_dataset.py(line 110) 11/241: 1oio A downloaded
2020-11-02 11:24:49,735 [DEBUG] download_dataset.py(line 110) 12/241: 1ld8 B downloaded
2020-11-02 11:24:49,828 [DEBUG] download_dataset.py(line 110) 13/241: 4eng A downloaded
2020-11-02 11:24:50,826 [DEBUG] download_dataset.py(line 110) 14/241: 1qgw C downloaded
2020-11-02 11:24:51,811 [DEBUG] download_dataset.py(line 110) 15/241: 3cx5 O downloaded
2020-11-02 11:24:51,811 [DEBUG] download_dataset.py(line 110) 16/241: 2r09 A downloaded
2020-11-02 11:24:51,811 [DEBUG] download_dataset.py(line 110) 17/241: 1d3c A downloaded
2020-11-02 11:24:51,821 [DEBUG] download_dataset.py(line 110) 18/241: 1al6 A downloaded
2020-11-02 11:24:53,871 [DEBUG] download_dataset.py(line 110) 19/241: 1dz4 A downloaded
2020-11-02 11:24:54,022 [DEBUG] download_dataset.py(line 110) 21/241: 1n9y C downloaded
2020-11-02 11:24:54,022 [DEBUG] download_dataset.py(line 110) 22/241: 1uyy A downloaded
2020-11-02 11:24:54,022 [DEBUG] download_dataset.py(line 110) 20/241: 1n8u A downloaded
2020-11-02 11:24:54,022 [DEBUG] download_dataset.py(line 110) 23/241: 1m6z B downloaded
2020-11-02 11:24:55,752 [DEBUG] download_dataset.py(line 110) 24/241: 2np5 A downloaded
