2020-08-19 17:11:24,841 [INFO] download_dataset.py(line 145) Downloading structures from /home/katebrich/Documents/diplomka/datasets/test.txt to /home/katebrich/Documents/diplomka/datasets/pipeline_test started...
2020-08-19 17:11:25,257 [ERROR] download_dataset.py(line 91) Error while downloading XXXX X: HTTP Error 404: Not Found
Traceback (most recent call last):
  File "./pythonScripts/download_dataset.py", line 83, in download_structure
    get_PDB(temp_file, output_PDB, pdb_id, chain_ids, ligands_filter)
  File "./pythonScripts/download_dataset.py", line 33, in get_PDB
    response = restAPI_get(url)
  File "/home/katebrich/Documents/diplomka/GitHub/pythonScripts/helper.py", line 41, in restAPI_get
    with urllib.request.urlopen(req) as f:
  File "/home/katebrich/anaconda3/lib/python3.7/urllib/request.py", line 222, in urlopen
    return opener.open(url, data, timeout)
  File "/home/katebrich/anaconda3/lib/python3.7/urllib/request.py", line 531, in open
    response = meth(req, response)
  File "/home/katebrich/anaconda3/lib/python3.7/urllib/request.py", line 641, in http_response
    'http', request, response, code, msg, hdrs)
  File "/home/katebrich/anaconda3/lib/python3.7/urllib/request.py", line 569, in error
    return self._call_chain(*args)
  File "/home/katebrich/anaconda3/lib/python3.7/urllib/request.py", line 503, in _call_chain
    result = func(*args)
  File "/home/katebrich/anaconda3/lib/python3.7/urllib/request.py", line 649, in http_error_default
    raise HTTPError(req.full_url, code, msg, hdrs, fp)
urllib.error.HTTPError: HTTP Error 404: Not Found
2020-08-19 17:11:25,262 [ERROR] download_dataset.py(line 101) 1/8: XXXX X NOT DOWNLOADED !
2020-08-19 17:11:44,696 [WARNING] download_dataset.py(line 166) Downloading structures finished: Some structures were not downloaded successfully: 
 XXXX X
2020-08-19 17:11:44,903 [INFO] create_mappings_cache.py(line 69) Creating mapping cache started...
2020-08-19 17:11:45,282 [ERROR] create_mappings_cache.py(line 25) Error while processing XXXX X: HTTP Error 404: Not Found
Traceback (most recent call last):
  File "./pythonScripts/create_mappings_cache.py", line 17, in create_mappings_cache
    mappings = res_mappings_author_to_pdbe(pdb_id, chain_id)
  File "/home/katebrich/Documents/diplomka/GitHub/pythonScripts/helper.py", line 112, in res_mappings_author_to_pdbe
    response = restAPI_get_json(f"https://www.ebi.ac.uk/pdbe/api/pdb/entry/residue_listing/{pdb_id}/chain/{chain_id}")
  File "/home/katebrich/Documents/diplomka/GitHub/pythonScripts/helper.py", line 47, in restAPI_get_json
    return json.loads(restAPI_get(url))
  File "/home/katebrich/Documents/diplomka/GitHub/pythonScripts/helper.py", line 41, in restAPI_get
    with urllib.request.urlopen(req) as f:
  File "/home/katebrich/anaconda3/lib/python3.7/urllib/request.py", line 222, in urlopen
    return opener.open(url, data, timeout)
  File "/home/katebrich/anaconda3/lib/python3.7/urllib/request.py", line 531, in open
    response = meth(req, response)
  File "/home/katebrich/anaconda3/lib/python3.7/urllib/request.py", line 641, in http_response
    'http', request, response, code, msg, hdrs)
  File "/home/katebrich/anaconda3/lib/python3.7/urllib/request.py", line 569, in error
    return self._call_chain(*args)
  File "/home/katebrich/anaconda3/lib/python3.7/urllib/request.py", line 503, in _call_chain
    result = func(*args)
  File "/home/katebrich/anaconda3/lib/python3.7/urllib/request.py", line 649, in http_error_default
    raise HTTPError(req.full_url, code, msg, hdrs, fp)
urllib.error.HTTPError: HTTP Error 404: Not Found
2020-08-19 17:11:45,284 [ERROR] create_mappings_cache.py(line 33) 1/8: XXXX X NOT PROCESSED !
2020-08-19 17:11:47,303 [WARNING] create_mappings_cache.py(line 89) Creating mapping cache finished: Some structures were not processed successfully: 
 XXXX X
2020-08-19 17:11:47,550 [INFO] compute_ligand_binding_sites.py(line 118) Computing ligand binding sites started...
2020-08-19 17:11:47,555 [ERROR] compute_ligand_binding_sites.py(line 26) Error while processing XXXX X: [Errno 2] No such file or directory: '/home/katebrich/Documents/diplomka/datasets/pipeline_test/PDB/XXXXX.pdb'
Traceback (most recent call last):
  File "./pythonScripts/compute_ligand_binding_sites.py", line 18, in __get_ligand_binding_site
    lbs = __compute_ligand_binding_sites(pdb_id, chain_id, pdb_path)
  File "./pythonScripts/compute_ligand_binding_sites.py", line 44, in __compute_ligand_binding_sites
    structure = parser.get_structure(pdb_id + chain_id, pdb_file_path)
  File "/home/katebrich/anaconda3/lib/python3.7/site-packages/Bio/PDB/PDBParser.py", line 88, in get_structure
    with as_handle(file, mode="rU") as handle:
  File "/home/katebrich/anaconda3/lib/python3.7/contextlib.py", line 112, in __enter__
    return next(self.gen)
  File "/home/katebrich/anaconda3/lib/python3.7/site-packages/Bio/File.py", line 120, in as_handle
    with open(handleish, mode, **kwargs) as fp:
FileNotFoundError: [Errno 2] No such file or directory: '/home/katebrich/Documents/diplomka/datasets/pipeline_test/PDB/XXXXX.pdb'
2020-08-19 17:11:47,602 [ERROR] compute_ligand_binding_sites.py(line 34) 1/8: XXXX X NOT PROCESSED !
2020-08-19 17:11:53,136 [WARNING] compute_ligand_binding_sites.py(line 138) Computing ligand binding sites finished: Some structures were not processed successfully: 
 XXXX X
2020-08-19 17:11:53,401 [INFO] compute_feature.py(line 81) Computing feature pKa_COOH started...
2020-08-19 17:11:53,411 [ERROR] compute_feature.py(line 28) Error while processing XXXX X: [Errno 2] No such file or directory: '/home/katebrich/Documents/diplomka/datasets/pipeline_test/FASTA/XXXXX.fasta'
Traceback (most recent call last):
  File "./pythonScripts/compute_feature.py", line 19, in __compute_feature
    feat_vals = get_feature(name_of_feature, input_dir, pdb_id, chain_id)
  File "/home/katebrich/Documents/diplomka/GitHub/pythonScripts/features.py", line 19, in get_feature
    return get_pKa_COOH(data_dir, pdb_id, chain_id)
  File "/home/katebrich/Documents/diplomka/GitHub/pythonScripts/features.py", line 63, in get_pKa_COOH
    return get_AA_properties(pKa_COOH, data_dir, pdb_id, chain_id)
  File "/home/katebrich/Documents/diplomka/GitHub/pythonScripts/features.py", line 244, in get_AA_properties
    seq = list(SeqIO.parse(fasta_file, "fasta"))[0]
  File "/home/katebrich/anaconda3/lib/python3.7/site-packages/Bio/SeqIO/FastaIO.py", line 178, in FastaIterator
    with as_handle(handle, "rU") as handle:
  File "/home/katebrich/anaconda3/lib/python3.7/contextlib.py", line 112, in __enter__
    return next(self.gen)
  File "/home/katebrich/anaconda3/lib/python3.7/site-packages/Bio/File.py", line 120, in as_handle
    with open(handleish, mode, **kwargs) as fp:
FileNotFoundError: [Errno 2] No such file or directory: '/home/katebrich/Documents/diplomka/datasets/pipeline_test/FASTA/XXXXX.fasta'
2020-08-19 17:11:53,418 [ERROR] compute_feature.py(line 36) 8/8: XXXX X NOT PROCESSED !
2020-08-19 17:11:53,418 [WARNING] compute_feature.py(line 102) Computing feature pKa_COOH finished: Some structures were not processed successfully: 
 XXXX X
2020-08-19 17:11:53,755 [INFO] compute_feature.py(line 81) Computing feature pKa_NH3 started...
2020-08-19 17:11:53,765 [ERROR] compute_feature.py(line 28) Error while processing XXXX X: [Errno 2] No such file or directory: '/home/katebrich/Documents/diplomka/datasets/pipeline_test/FASTA/XXXXX.fasta'
Traceback (most recent call last):
  File "./pythonScripts/compute_feature.py", line 19, in __compute_feature
    feat_vals = get_feature(name_of_feature, input_dir, pdb_id, chain_id)
  File "/home/katebrich/Documents/diplomka/GitHub/pythonScripts/features.py", line 21, in get_feature
    return get_pKa_NH3(data_dir, pdb_id, chain_id)
  File "/home/katebrich/Documents/diplomka/GitHub/pythonScripts/features.py", line 66, in get_pKa_NH3
    return get_AA_properties(pKa_NH3, data_dir, pdb_id, chain_id)
  File "/home/katebrich/Documents/diplomka/GitHub/pythonScripts/features.py", line 244, in get_AA_properties
    seq = list(SeqIO.parse(fasta_file, "fasta"))[0]
  File "/home/katebrich/anaconda3/lib/python3.7/site-packages/Bio/SeqIO/FastaIO.py", line 178, in FastaIterator
    with as_handle(handle, "rU") as handle:
  File "/home/katebrich/anaconda3/lib/python3.7/contextlib.py", line 112, in __enter__
    return next(self.gen)
  File "/home/katebrich/anaconda3/lib/python3.7/site-packages/Bio/File.py", line 120, in as_handle
    with open(handleish, mode, **kwargs) as fp:
FileNotFoundError: [Errno 2] No such file or directory: '/home/katebrich/Documents/diplomka/datasets/pipeline_test/FASTA/XXXXX.fasta'
2020-08-19 17:11:53,772 [ERROR] compute_feature.py(line 36) 8/8: XXXX X NOT PROCESSED !
2020-08-19 17:11:53,772 [WARNING] compute_feature.py(line 102) Computing feature pKa_NH3 finished: Some structures were not processed successfully: 
 XXXX X
2020-08-19 17:11:54,092 [INFO] compute_feature.py(line 81) Computing feature molecular_weight started...
2020-08-19 17:11:54,102 [ERROR] compute_feature.py(line 28) Error while processing XXXX X: [Errno 2] No such file or directory: '/home/katebrich/Documents/diplomka/datasets/pipeline_test/FASTA/XXXXX.fasta'
Traceback (most recent call last):
  File "./pythonScripts/compute_feature.py", line 19, in __compute_feature
    feat_vals = get_feature(name_of_feature, input_dir, pdb_id, chain_id)
  File "/home/katebrich/Documents/diplomka/GitHub/pythonScripts/features.py", line 23, in get_feature
    return get_molecular_weight(data_dir, pdb_id, chain_id)
  File "/home/katebrich/Documents/diplomka/GitHub/pythonScripts/features.py", line 60, in get_molecular_weight
    return get_AA_properties(molecular_weight, data_dir, pdb_id, chain_id)
  File "/home/katebrich/Documents/diplomka/GitHub/pythonScripts/features.py", line 244, in get_AA_properties
    seq = list(SeqIO.parse(fasta_file, "fasta"))[0]
  File "/home/katebrich/anaconda3/lib/python3.7/site-packages/Bio/SeqIO/FastaIO.py", line 178, in FastaIterator
    with as_handle(handle, "rU") as handle:
  File "/home/katebrich/anaconda3/lib/python3.7/contextlib.py", line 112, in __enter__
    return next(self.gen)
  File "/home/katebrich/anaconda3/lib/python3.7/site-packages/Bio/File.py", line 120, in as_handle
    with open(handleish, mode, **kwargs) as fp:
FileNotFoundError: [Errno 2] No such file or directory: '/home/katebrich/Documents/diplomka/datasets/pipeline_test/FASTA/XXXXX.fasta'
2020-08-19 17:11:54,109 [ERROR] compute_feature.py(line 36) 8/8: XXXX X NOT PROCESSED !
2020-08-19 17:11:54,109 [WARNING] compute_feature.py(line 102) Computing feature molecular_weight finished: Some structures were not processed successfully: 
 XXXX X
2020-08-19 17:11:54,428 [INFO] compute_feature.py(line 81) Computing feature unp_variants started...
2020-08-19 17:11:54,784 [ERROR] compute_feature.py(line 28) Error while processing XXXX X: HTTP Error 404: Not Found
Traceback (most recent call last):
  File "./pythonScripts/compute_feature.py", line 19, in __compute_feature
    feat_vals = get_feature(name_of_feature, input_dir, pdb_id, chain_id)
  File "/home/katebrich/Documents/diplomka/GitHub/pythonScripts/features.py", line 13, in get_feature
    return get_variants(data_dir, pdb_id, chain_id)
  File "/home/katebrich/Documents/diplomka/GitHub/pythonScripts/features.py", line 152, in get_variants
    entities = get_uniprot_entity(pdb_id, chain_id)
  File "/home/katebrich/Documents/diplomka/GitHub/pythonScripts/helper.py", line 12, in get_uniprot_entity
    parsedResponse = restAPI_get_json(url)
  File "/home/katebrich/Documents/diplomka/GitHub/pythonScripts/helper.py", line 47, in restAPI_get_json
    return json.loads(restAPI_get(url))
  File "/home/katebrich/Documents/diplomka/GitHub/pythonScripts/helper.py", line 41, in restAPI_get
    with urllib.request.urlopen(req) as f:
  File "/home/katebrich/anaconda3/lib/python3.7/urllib/request.py", line 222, in urlopen
    return opener.open(url, data, timeout)
  File "/home/katebrich/anaconda3/lib/python3.7/urllib/request.py", line 531, in open
    response = meth(req, response)
  File "/home/katebrich/anaconda3/lib/python3.7/urllib/request.py", line 641, in http_response
    'http', request, response, code, msg, hdrs)
  File "/home/katebrich/anaconda3/lib/python3.7/urllib/request.py", line 569, in error
    return self._call_chain(*args)
  File "/home/katebrich/anaconda3/lib/python3.7/urllib/request.py", line 503, in _call_chain
    result = func(*args)
  File "/home/katebrich/anaconda3/lib/python3.7/urllib/request.py", line 649, in http_error_default
    raise HTTPError(req.full_url, code, msg, hdrs, fp)
urllib.error.HTTPError: HTTP Error 404: Not Found
2020-08-19 17:11:54,811 [ERROR] compute_feature.py(line 36) 1/8: XXXX X NOT PROCESSED !
2020-08-19 17:12:01,878 [WARNING] compute_feature.py(line 102) Computing feature unp_variants finished: Some structures were not processed successfully: 
 XXXX X
2020-08-19 17:12:02,142 [INFO] compute_feature.py(line 81) Computing feature hydropathy started...
2020-08-19 17:12:02,153 [ERROR] compute_feature.py(line 28) Error while processing XXXX X: [Errno 2] No such file or directory: '/home/katebrich/Documents/diplomka/datasets/pipeline_test/FASTA/XXXXX.fasta'
Traceback (most recent call last):
  File "./pythonScripts/compute_feature.py", line 19, in __compute_feature
    feat_vals = get_feature(name_of_feature, input_dir, pdb_id, chain_id)
  File "/home/katebrich/Documents/diplomka/GitHub/pythonScripts/features.py", line 17, in get_feature
    return get_hydropathy_kyte_doolitle(data_dir, pdb_id, chain_id)
  File "/home/katebrich/Documents/diplomka/GitHub/pythonScripts/features.py", line 57, in get_hydropathy_kyte_doolitle
    return get_AA_properties(hydropathy_kyte_doolitle, data_dir, pdb_id, chain_id)
  File "/home/katebrich/Documents/diplomka/GitHub/pythonScripts/features.py", line 244, in get_AA_properties
    seq = list(SeqIO.parse(fasta_file, "fasta"))[0]
  File "/home/katebrich/anaconda3/lib/python3.7/site-packages/Bio/SeqIO/FastaIO.py", line 178, in FastaIterator
    with as_handle(handle, "rU") as handle:
  File "/home/katebrich/anaconda3/lib/python3.7/contextlib.py", line 112, in __enter__
    return next(self.gen)
  File "/home/katebrich/anaconda3/lib/python3.7/site-packages/Bio/File.py", line 120, in as_handle
    with open(handleish, mode, **kwargs) as fp:
FileNotFoundError: [Errno 2] No such file or directory: '/home/katebrich/Documents/diplomka/datasets/pipeline_test/FASTA/XXXXX.fasta'
2020-08-19 17:12:02,160 [ERROR] compute_feature.py(line 36) 8/8: XXXX X NOT PROCESSED !
2020-08-19 17:12:02,160 [WARNING] compute_feature.py(line 102) Computing feature hydropathy finished: Some structures were not processed successfully: 
 XXXX X
2020-08-19 17:12:02,481 [INFO] compute_feature.py(line 81) Computing feature unp_PTM started...
2020-08-19 17:12:02,873 [ERROR] compute_feature.py(line 28) Error while processing XXXX X: HTTP Error 404: Not Found
Traceback (most recent call last):
  File "./pythonScripts/compute_feature.py", line 19, in __compute_feature
    feat_vals = get_feature(name_of_feature, input_dir, pdb_id, chain_id)
  File "/home/katebrich/Documents/diplomka/GitHub/pythonScripts/features.py", line 9, in get_feature
    return get_PTM(data_dir, pdb_id, chain_id)
  File "/home/katebrich/Documents/diplomka/GitHub/pythonScripts/features.py", line 69, in get_PTM
    entities = get_uniprot_entity(pdb_id, chain_id)
  File "/home/katebrich/Documents/diplomka/GitHub/pythonScripts/helper.py", line 12, in get_uniprot_entity
    parsedResponse = restAPI_get_json(url)
  File "/home/katebrich/Documents/diplomka/GitHub/pythonScripts/helper.py", line 47, in restAPI_get_json
    return json.loads(restAPI_get(url))
  File "/home/katebrich/Documents/diplomka/GitHub/pythonScripts/helper.py", line 41, in restAPI_get
    with urllib.request.urlopen(req) as f:
  File "/home/katebrich/anaconda3/lib/python3.7/urllib/request.py", line 222, in urlopen
    return opener.open(url, data, timeout)
  File "/home/katebrich/anaconda3/lib/python3.7/urllib/request.py", line 531, in open
    response = meth(req, response)
  File "/home/katebrich/anaconda3/lib/python3.7/urllib/request.py", line 641, in http_response
    'http', request, response, code, msg, hdrs)
  File "/home/katebrich/anaconda3/lib/python3.7/urllib/request.py", line 569, in error
    return self._call_chain(*args)
  File "/home/katebrich/anaconda3/lib/python3.7/urllib/request.py", line 503, in _call_chain
    result = func(*args)
  File "/home/katebrich/anaconda3/lib/python3.7/urllib/request.py", line 649, in http_error_default
    raise HTTPError(req.full_url, code, msg, hdrs, fp)
urllib.error.HTTPError: HTTP Error 404: Not Found
2020-08-19 17:12:02,900 [ERROR] compute_feature.py(line 36) 1/8: XXXX X NOT PROCESSED !
2020-08-19 17:12:08,533 [WARNING] compute_feature.py(line 102) Computing feature unp_PTM finished: Some structures were not processed successfully: 
 XXXX X
2020-08-19 17:12:08,771 [INFO] compute_feature.py(line 81) Computing feature unp_glycosylation started...
2020-08-19 17:12:09,130 [ERROR] compute_feature.py(line 28) Error while processing XXXX X: HTTP Error 404: Not Found
Traceback (most recent call last):
  File "./pythonScripts/compute_feature.py", line 19, in __compute_feature
    feat_vals = get_feature(name_of_feature, input_dir, pdb_id, chain_id)
  File "/home/katebrich/Documents/diplomka/GitHub/pythonScripts/features.py", line 11, in get_feature
    return get_glycosylation(data_dir, pdb_id, chain_id)
  File "/home/katebrich/Documents/diplomka/GitHub/pythonScripts/features.py", line 111, in get_glycosylation
    entities = get_uniprot_entity(pdb_id, chain_id)
  File "/home/katebrich/Documents/diplomka/GitHub/pythonScripts/helper.py", line 12, in get_uniprot_entity
    parsedResponse = restAPI_get_json(url)
  File "/home/katebrich/Documents/diplomka/GitHub/pythonScripts/helper.py", line 47, in restAPI_get_json
    return json.loads(restAPI_get(url))
  File "/home/katebrich/Documents/diplomka/GitHub/pythonScripts/helper.py", line 41, in restAPI_get
    with urllib.request.urlopen(req) as f:
  File "/home/katebrich/anaconda3/lib/python3.7/urllib/request.py", line 222, in urlopen
    return opener.open(url, data, timeout)
  File "/home/katebrich/anaconda3/lib/python3.7/urllib/request.py", line 531, in open
    response = meth(req, response)
  File "/home/katebrich/anaconda3/lib/python3.7/urllib/request.py", line 641, in http_response
    'http', request, response, code, msg, hdrs)
  File "/home/katebrich/anaconda3/lib/python3.7/urllib/request.py", line 569, in error
    return self._call_chain(*args)
  File "/home/katebrich/anaconda3/lib/python3.7/urllib/request.py", line 503, in _call_chain
    result = func(*args)
  File "/home/katebrich/anaconda3/lib/python3.7/urllib/request.py", line 649, in http_error_default
    raise HTTPError(req.full_url, code, msg, hdrs, fp)
urllib.error.HTTPError: HTTP Error 404: Not Found
2020-08-19 17:12:09,164 [ERROR] compute_feature.py(line 36) 1/8: XXXX X NOT PROCESSED !
2020-08-19 17:12:14,914 [WARNING] compute_feature.py(line 102) Computing feature unp_glycosylation finished: Some structures were not processed successfully: 
 XXXX X
2020-08-19 17:12:15,744 [INFO] run_analysis.py(line 107) Running analysis started...
2020-08-19 17:12:15,745 [ERROR] run_analysis.py(line 48) Error while processing XXXX X: /home/katebrich/Documents/diplomka/datasets/pipeline_test/lbs/XXXXX.txt not found.
Traceback (most recent call last):
  File "./pythonScripts/run_analysis.py", line 24, in compute_pairs
    lbs = np.genfromtxt(file, delimiter=' ')
  File "/home/katebrich/anaconda3/lib/python3.7/site-packages/numpy/lib/npyio.py", line 1772, in genfromtxt
    fid = np.lib._datasource.open(fname, 'rt', encoding=encoding)
  File "/home/katebrich/anaconda3/lib/python3.7/site-packages/numpy/lib/_datasource.py", line 269, in open
    return ds.open(path, mode, encoding=encoding, newline=newline)
  File "/home/katebrich/anaconda3/lib/python3.7/site-packages/numpy/lib/_datasource.py", line 623, in open
    raise IOError("%s not found." % path)
OSError: /home/katebrich/Documents/diplomka/datasets/pipeline_test/lbs/XXXXX.txt not found.
2020-08-19 17:12:15,745 [ERROR] run_analysis.py(line 54) 2/8: XXXX X NOT PROCESSED !
2020-08-19 17:12:15,765 [WARNING] run_analysis.py(line 121) Some structures were not processed successfully: skipping them in the analysis...
 XXXX X
2020-08-19 17:12:15,768 [INFO] run_analysis.py(line 137) Running analysis finished. Results saved to /home/katebrich/Documents/diplomka/datasets/pipeline_test/analysis/pKa_COOH/results.txt
2020-08-19 17:12:16,647 [INFO] run_analysis.py(line 107) Running analysis started...
2020-08-19 17:12:16,647 [ERROR] run_analysis.py(line 48) Error while processing XXXX X: /home/katebrich/Documents/diplomka/datasets/pipeline_test/lbs/XXXXX.txt not found.
Traceback (most recent call last):
  File "./pythonScripts/run_analysis.py", line 24, in compute_pairs
    lbs = np.genfromtxt(file, delimiter=' ')
  File "/home/katebrich/anaconda3/lib/python3.7/site-packages/numpy/lib/npyio.py", line 1772, in genfromtxt
    fid = np.lib._datasource.open(fname, 'rt', encoding=encoding)
  File "/home/katebrich/anaconda3/lib/python3.7/site-packages/numpy/lib/_datasource.py", line 269, in open
    return ds.open(path, mode, encoding=encoding, newline=newline)
  File "/home/katebrich/anaconda3/lib/python3.7/site-packages/numpy/lib/_datasource.py", line 623, in open
    raise IOError("%s not found." % path)
OSError: /home/katebrich/Documents/diplomka/datasets/pipeline_test/lbs/XXXXX.txt not found.
2020-08-19 17:12:16,648 [ERROR] run_analysis.py(line 54) 2/8: XXXX X NOT PROCESSED !
2020-08-19 17:12:16,667 [WARNING] run_analysis.py(line 121) Some structures were not processed successfully: skipping them in the analysis...
 XXXX X
2020-08-19 17:12:16,670 [INFO] run_analysis.py(line 137) Running analysis finished. Results saved to /home/katebrich/Documents/diplomka/datasets/pipeline_test/analysis/pKa_NH3/results.txt
2020-08-19 17:12:17,530 [INFO] run_analysis.py(line 107) Running analysis started...
2020-08-19 17:12:17,531 [ERROR] run_analysis.py(line 48) Error while processing XXXX X: /home/katebrich/Documents/diplomka/datasets/pipeline_test/lbs/XXXXX.txt not found.
Traceback (most recent call last):
  File "./pythonScripts/run_analysis.py", line 24, in compute_pairs
    lbs = np.genfromtxt(file, delimiter=' ')
  File "/home/katebrich/anaconda3/lib/python3.7/site-packages/numpy/lib/npyio.py", line 1772, in genfromtxt
    fid = np.lib._datasource.open(fname, 'rt', encoding=encoding)
  File "/home/katebrich/anaconda3/lib/python3.7/site-packages/numpy/lib/_datasource.py", line 269, in open
    return ds.open(path, mode, encoding=encoding, newline=newline)
  File "/home/katebrich/anaconda3/lib/python3.7/site-packages/numpy/lib/_datasource.py", line 623, in open
    raise IOError("%s not found." % path)
OSError: /home/katebrich/Documents/diplomka/datasets/pipeline_test/lbs/XXXXX.txt not found.
2020-08-19 17:12:17,532 [ERROR] run_analysis.py(line 54) 2/8: XXXX X NOT PROCESSED !
2020-08-19 17:12:17,551 [WARNING] run_analysis.py(line 121) Some structures were not processed successfully: skipping them in the analysis...
 XXXX X
2020-08-19 17:12:17,554 [INFO] run_analysis.py(line 137) Running analysis finished. Results saved to /home/katebrich/Documents/diplomka/datasets/pipeline_test/analysis/molecular_weight/results.txt
2020-08-19 17:12:18,409 [INFO] run_analysis.py(line 107) Running analysis started...
2020-08-19 17:12:18,410 [ERROR] run_analysis.py(line 48) Error while processing XXXX X: /home/katebrich/Documents/diplomka/datasets/pipeline_test/lbs/XXXXX.txt not found.
Traceback (most recent call last):
  File "./pythonScripts/run_analysis.py", line 24, in compute_pairs
    lbs = np.genfromtxt(file, delimiter=' ')
  File "/home/katebrich/anaconda3/lib/python3.7/site-packages/numpy/lib/npyio.py", line 1772, in genfromtxt
    fid = np.lib._datasource.open(fname, 'rt', encoding=encoding)
  File "/home/katebrich/anaconda3/lib/python3.7/site-packages/numpy/lib/_datasource.py", line 269, in open
    return ds.open(path, mode, encoding=encoding, newline=newline)
  File "/home/katebrich/anaconda3/lib/python3.7/site-packages/numpy/lib/_datasource.py", line 623, in open
    raise IOError("%s not found." % path)
OSError: /home/katebrich/Documents/diplomka/datasets/pipeline_test/lbs/XXXXX.txt not found.
2020-08-19 17:12:18,411 [ERROR] run_analysis.py(line 54) 2/8: XXXX X NOT PROCESSED !
2020-08-19 17:12:18,430 [WARNING] run_analysis.py(line 121) Some structures were not processed successfully: skipping them in the analysis...
 XXXX X
2020-08-19 17:12:18,432 [INFO] run_analysis.py(line 137) Running analysis finished. Results saved to /home/katebrich/Documents/diplomka/datasets/pipeline_test/analysis/unp_variants/results.txt
2020-08-19 17:12:19,278 [INFO] run_analysis.py(line 107) Running analysis started...
2020-08-19 17:12:19,279 [ERROR] run_analysis.py(line 48) Error while processing XXXX X: /home/katebrich/Documents/diplomka/datasets/pipeline_test/lbs/XXXXX.txt not found.
Traceback (most recent call last):
  File "./pythonScripts/run_analysis.py", line 24, in compute_pairs
    lbs = np.genfromtxt(file, delimiter=' ')
  File "/home/katebrich/anaconda3/lib/python3.7/site-packages/numpy/lib/npyio.py", line 1772, in genfromtxt
    fid = np.lib._datasource.open(fname, 'rt', encoding=encoding)
  File "/home/katebrich/anaconda3/lib/python3.7/site-packages/numpy/lib/_datasource.py", line 269, in open
    return ds.open(path, mode, encoding=encoding, newline=newline)
  File "/home/katebrich/anaconda3/lib/python3.7/site-packages/numpy/lib/_datasource.py", line 623, in open
    raise IOError("%s not found." % path)
OSError: /home/katebrich/Documents/diplomka/datasets/pipeline_test/lbs/XXXXX.txt not found.
2020-08-19 17:12:19,280 [ERROR] run_analysis.py(line 54) 2/8: XXXX X NOT PROCESSED !
2020-08-19 17:12:19,299 [WARNING] run_analysis.py(line 121) Some structures were not processed successfully: skipping them in the analysis...
 XXXX X
2020-08-19 17:12:19,302 [INFO] run_analysis.py(line 137) Running analysis finished. Results saved to /home/katebrich/Documents/diplomka/datasets/pipeline_test/analysis/hydropathy/results.txt
2020-08-19 17:12:20,161 [INFO] run_analysis.py(line 107) Running analysis started...
2020-08-19 17:12:20,162 [ERROR] run_analysis.py(line 48) Error while processing XXXX X: /home/katebrich/Documents/diplomka/datasets/pipeline_test/lbs/XXXXX.txt not found.
Traceback (most recent call last):
  File "./pythonScripts/run_analysis.py", line 24, in compute_pairs
    lbs = np.genfromtxt(file, delimiter=' ')
  File "/home/katebrich/anaconda3/lib/python3.7/site-packages/numpy/lib/npyio.py", line 1772, in genfromtxt
    fid = np.lib._datasource.open(fname, 'rt', encoding=encoding)
  File "/home/katebrich/anaconda3/lib/python3.7/site-packages/numpy/lib/_datasource.py", line 269, in open
    return ds.open(path, mode, encoding=encoding, newline=newline)
  File "/home/katebrich/anaconda3/lib/python3.7/site-packages/numpy/lib/_datasource.py", line 623, in open
    raise IOError("%s not found." % path)
OSError: /home/katebrich/Documents/diplomka/datasets/pipeline_test/lbs/XXXXX.txt not found.
2020-08-19 17:12:20,163 [ERROR] run_analysis.py(line 54) 2/8: XXXX X NOT PROCESSED !
2020-08-19 17:12:20,182 [WARNING] run_analysis.py(line 121) Some structures were not processed successfully: skipping them in the analysis...
 XXXX X
2020-08-19 17:12:20,184 [INFO] run_analysis.py(line 137) Running analysis finished. Results saved to /home/katebrich/Documents/diplomka/datasets/pipeline_test/analysis/unp_PTM/results.txt
2020-08-19 17:12:21,054 [INFO] run_analysis.py(line 107) Running analysis started...
2020-08-19 17:12:21,055 [ERROR] run_analysis.py(line 48) Error while processing XXXX X: /home/katebrich/Documents/diplomka/datasets/pipeline_test/lbs/XXXXX.txt not found.
Traceback (most recent call last):
  File "./pythonScripts/run_analysis.py", line 24, in compute_pairs
    lbs = np.genfromtxt(file, delimiter=' ')
  File "/home/katebrich/anaconda3/lib/python3.7/site-packages/numpy/lib/npyio.py", line 1772, in genfromtxt
    fid = np.lib._datasource.open(fname, 'rt', encoding=encoding)
  File "/home/katebrich/anaconda3/lib/python3.7/site-packages/numpy/lib/_datasource.py", line 269, in open
    return ds.open(path, mode, encoding=encoding, newline=newline)
  File "/home/katebrich/anaconda3/lib/python3.7/site-packages/numpy/lib/_datasource.py", line 623, in open
    raise IOError("%s not found." % path)
OSError: /home/katebrich/Documents/diplomka/datasets/pipeline_test/lbs/XXXXX.txt not found.
2020-08-19 17:12:21,056 [ERROR] run_analysis.py(line 54) 2/8: XXXX X NOT PROCESSED !
2020-08-19 17:12:21,074 [WARNING] run_analysis.py(line 121) Some structures were not processed successfully: skipping them in the analysis...
 XXXX X
2020-08-19 17:12:21,075 [INFO] run_analysis.py(line 137) Running analysis finished. Results saved to /home/katebrich/Documents/diplomka/datasets/pipeline_test/analysis/unp_glycosylation/results.txt
2020-08-19 17:47:28,406 [INFO] compute_feature.py(line 81) Computing feature pKa_COOH started...
2020-08-19 17:47:28,416 [ERROR] compute_feature.py(line 28) Error while processing XXXX X: [Errno 2] No such file or directory: '/home/katebrich/Documents/diplomka/datasets/pipeline_test/FASTA/XXXXX.fasta'
Traceback (most recent call last):
  File "./pythonScripts/compute_feature.py", line 19, in __compute_feature
    feat_vals = get_feature(name_of_feature, input_dir, pdb_id, chain_id)
  File "/home/katebrich/Documents/diplomka/GitHub/pythonScripts/features.py", line 21, in get_feature
    return get_pKa_COOH(data_dir, pdb_id, chain_id)
  File "/home/katebrich/Documents/diplomka/GitHub/pythonScripts/features.py", line 65, in get_pKa_COOH
    return get_AA_properties(pKa_COOH, data_dir, pdb_id, chain_id)
  File "/home/katebrich/Documents/diplomka/GitHub/pythonScripts/features.py", line 275, in get_AA_properties
    seq = list(SeqIO.parse(fasta_file, "fasta"))[0]
  File "/home/katebrich/anaconda3/lib/python3.7/site-packages/Bio/SeqIO/FastaIO.py", line 178, in FastaIterator
    with as_handle(handle, "rU") as handle:
  File "/home/katebrich/anaconda3/lib/python3.7/contextlib.py", line 112, in __enter__
    return next(self.gen)
  File "/home/katebrich/anaconda3/lib/python3.7/site-packages/Bio/File.py", line 120, in as_handle
    with open(handleish, mode, **kwargs) as fp:
FileNotFoundError: [Errno 2] No such file or directory: '/home/katebrich/Documents/diplomka/datasets/pipeline_test/FASTA/XXXXX.fasta'
2020-08-19 17:47:28,416 [ERROR] compute_feature.py(line 28) Error while processing 2g46 A: [Errno 2] No such file or directory: '/home/katebrich/Documents/diplomka/datasets/pipeline_test/FASTA/2g46A.fasta'
Traceback (most recent call last):
  File "./pythonScripts/compute_feature.py", line 19, in __compute_feature
    feat_vals = get_feature(name_of_feature, input_dir, pdb_id, chain_id)
  File "/home/katebrich/Documents/diplomka/GitHub/pythonScripts/features.py", line 21, in get_feature
    return get_pKa_COOH(data_dir, pdb_id, chain_id)
  File "/home/katebrich/Documents/diplomka/GitHub/pythonScripts/features.py", line 65, in get_pKa_COOH
    return get_AA_properties(pKa_COOH, data_dir, pdb_id, chain_id)
  File "/home/katebrich/Documents/diplomka/GitHub/pythonScripts/features.py", line 275, in get_AA_properties
    seq = list(SeqIO.parse(fasta_file, "fasta"))[0]
  File "/home/katebrich/anaconda3/lib/python3.7/site-packages/Bio/SeqIO/FastaIO.py", line 178, in FastaIterator
    with as_handle(handle, "rU") as handle:
  File "/home/katebrich/anaconda3/lib/python3.7/contextlib.py", line 112, in __enter__
    return next(self.gen)
  File "/home/katebrich/anaconda3/lib/python3.7/site-packages/Bio/File.py", line 120, in as_handle
    with open(handleish, mode, **kwargs) as fp:
FileNotFoundError: [Errno 2] No such file or directory: '/home/katebrich/Documents/diplomka/datasets/pipeline_test/FASTA/2g46A.fasta'
2020-08-19 17:47:28,417 [ERROR] compute_feature.py(line 28) Error while processing 148l E: [Errno 2] No such file or directory: '/home/katebrich/Documents/diplomka/datasets/pipeline_test/FASTA/148lE.fasta'
Traceback (most recent call last):
  File "./pythonScripts/compute_feature.py", line 19, in __compute_feature
    feat_vals = get_feature(name_of_feature, input_dir, pdb_id, chain_id)
  File "/home/katebrich/Documents/diplomka/GitHub/pythonScripts/features.py", line 21, in get_feature
    return get_pKa_COOH(data_dir, pdb_id, chain_id)
  File "/home/katebrich/Documents/diplomka/GitHub/pythonScripts/features.py", line 65, in get_pKa_COOH
    return get_AA_properties(pKa_COOH, data_dir, pdb_id, chain_id)
  File "/home/katebrich/Documents/diplomka/GitHub/pythonScripts/features.py", line 275, in get_AA_properties
    seq = list(SeqIO.parse(fasta_file, "fasta"))[0]
  File "/home/katebrich/anaconda3/lib/python3.7/site-packages/Bio/SeqIO/FastaIO.py", line 178, in FastaIterator
    with as_handle(handle, "rU") as handle:
  File "/home/katebrich/anaconda3/lib/python3.7/contextlib.py", line 112, in __enter__
    return next(self.gen)
  File "/home/katebrich/anaconda3/lib/python3.7/site-packages/Bio/File.py", line 120, in as_handle
    with open(handleish, mode, **kwargs) as fp:
FileNotFoundError: [Errno 2] No such file or directory: '/home/katebrich/Documents/diplomka/datasets/pipeline_test/FASTA/148lE.fasta'
2020-08-19 17:47:28,417 [ERROR] compute_feature.py(line 28) Error while processing 1igy B: [Errno 2] No such file or directory: '/home/katebrich/Documents/diplomka/datasets/pipeline_test/FASTA/1igyB.fasta'
Traceback (most recent call last):
  File "./pythonScripts/compute_feature.py", line 19, in __compute_feature
    feat_vals = get_feature(name_of_feature, input_dir, pdb_id, chain_id)
  File "/home/katebrich/Documents/diplomka/GitHub/pythonScripts/features.py", line 21, in get_feature
    return get_pKa_COOH(data_dir, pdb_id, chain_id)
  File "/home/katebrich/Documents/diplomka/GitHub/pythonScripts/features.py", line 65, in get_pKa_COOH
    return get_AA_properties(pKa_COOH, data_dir, pdb_id, chain_id)
  File "/home/katebrich/Documents/diplomka/GitHub/pythonScripts/features.py", line 275, in get_AA_properties
    seq = list(SeqIO.parse(fasta_file, "fasta"))[0]
  File "/home/katebrich/anaconda3/lib/python3.7/site-packages/Bio/SeqIO/FastaIO.py", line 178, in FastaIterator
    with as_handle(handle, "rU") as handle:
  File "/home/katebrich/anaconda3/lib/python3.7/contextlib.py", line 112, in __enter__
    return next(self.gen)
  File "/home/katebrich/anaconda3/lib/python3.7/site-packages/Bio/File.py", line 120, in as_handle
    with open(handleish, mode, **kwargs) as fp:
FileNotFoundError: [Errno 2] No such file or directory: '/home/katebrich/Documents/diplomka/datasets/pipeline_test/FASTA/1igyB.fasta'
2020-08-19 17:47:28,418 [ERROR] compute_feature.py(line 36) 1/8: XXXX X NOT PROCESSED !
2020-08-19 17:47:28,418 [ERROR] compute_feature.py(line 36) 2/8: 2g46 A NOT PROCESSED !
2020-08-19 17:47:28,418 [ERROR] compute_feature.py(line 36) 3/8: 148l E NOT PROCESSED !
2020-08-19 17:47:28,418 [ERROR] compute_feature.py(line 36) 4/8: 1igy B NOT PROCESSED !
2020-08-19 17:47:28,419 [ERROR] compute_feature.py(line 28) Error while processing 1exa A: [Errno 2] No such file or directory: '/home/katebrich/Documents/diplomka/datasets/pipeline_test/FASTA/1exaA.fasta'
Traceback (most recent call last):
  File "./pythonScripts/compute_feature.py", line 19, in __compute_feature
    feat_vals = get_feature(name_of_feature, input_dir, pdb_id, chain_id)
  File "/home/katebrich/Documents/diplomka/GitHub/pythonScripts/features.py", line 21, in get_feature
    return get_pKa_COOH(data_dir, pdb_id, chain_id)
  File "/home/katebrich/Documents/diplomka/GitHub/pythonScripts/features.py", line 65, in get_pKa_COOH
    return get_AA_properties(pKa_COOH, data_dir, pdb_id, chain_id)
  File "/home/katebrich/Documents/diplomka/GitHub/pythonScripts/features.py", line 275, in get_AA_properties
    seq = list(SeqIO.parse(fasta_file, "fasta"))[0]
  File "/home/katebrich/anaconda3/lib/python3.7/site-packages/Bio/SeqIO/FastaIO.py", line 178, in FastaIterator
    with as_handle(handle, "rU") as handle:
  File "/home/katebrich/anaconda3/lib/python3.7/contextlib.py", line 112, in __enter__
    return next(self.gen)
  File "/home/katebrich/anaconda3/lib/python3.7/site-packages/Bio/File.py", line 120, in as_handle
    with open(handleish, mode, **kwargs) as fp:
FileNotFoundError: [Errno 2] No such file or directory: '/home/katebrich/Documents/diplomka/datasets/pipeline_test/FASTA/1exaA.fasta'
2020-08-19 17:47:28,419 [ERROR] compute_feature.py(line 28) Error while processing 1qhi A: [Errno 2] No such file or directory: '/home/katebrich/Documents/diplomka/datasets/pipeline_test/FASTA/1qhiA.fasta'
Traceback (most recent call last):
  File "./pythonScripts/compute_feature.py", line 19, in __compute_feature
    feat_vals = get_feature(name_of_feature, input_dir, pdb_id, chain_id)
  File "/home/katebrich/Documents/diplomka/GitHub/pythonScripts/features.py", line 21, in get_feature
    return get_pKa_COOH(data_dir, pdb_id, chain_id)
  File "/home/katebrich/Documents/diplomka/GitHub/pythonScripts/features.py", line 65, in get_pKa_COOH
    return get_AA_properties(pKa_COOH, data_dir, pdb_id, chain_id)
  File "/home/katebrich/Documents/diplomka/GitHub/pythonScripts/features.py", line 275, in get_AA_properties
    seq = list(SeqIO.parse(fasta_file, "fasta"))[0]
  File "/home/katebrich/anaconda3/lib/python3.7/site-packages/Bio/SeqIO/FastaIO.py", line 178, in FastaIterator
    with as_handle(handle, "rU") as handle:
  File "/home/katebrich/anaconda3/lib/python3.7/contextlib.py", line 112, in __enter__
    return next(self.gen)
  File "/home/katebrich/anaconda3/lib/python3.7/site-packages/Bio/File.py", line 120, in as_handle
    with open(handleish, mode, **kwargs) as fp:
FileNotFoundError: [Errno 2] No such file or directory: '/home/katebrich/Documents/diplomka/datasets/pipeline_test/FASTA/1qhiA.fasta'
2020-08-19 17:47:28,419 [ERROR] compute_feature.py(line 28) Error while processing 3ldk A: [Errno 2] No such file or directory: '/home/katebrich/Documents/diplomka/datasets/pipeline_test/FASTA/3ldkA.fasta'
Traceback (most recent call last):
  File "./pythonScripts/compute_feature.py", line 19, in __compute_feature
    feat_vals = get_feature(name_of_feature, input_dir, pdb_id, chain_id)
  File "/home/katebrich/Documents/diplomka/GitHub/pythonScripts/features.py", line 21, in get_feature
    return get_pKa_COOH(data_dir, pdb_id, chain_id)
  File "/home/katebrich/Documents/diplomka/GitHub/pythonScripts/features.py", line 65, in get_pKa_COOH
    return get_AA_properties(pKa_COOH, data_dir, pdb_id, chain_id)
  File "/home/katebrich/Documents/diplomka/GitHub/pythonScripts/features.py", line 275, in get_AA_properties
    seq = list(SeqIO.parse(fasta_file, "fasta"))[0]
  File "/home/katebrich/anaconda3/lib/python3.7/site-packages/Bio/SeqIO/FastaIO.py", line 178, in FastaIterator
    with as_handle(handle, "rU") as handle:
  File "/home/katebrich/anaconda3/lib/python3.7/contextlib.py", line 112, in __enter__
    return next(self.gen)
  File "/home/katebrich/anaconda3/lib/python3.7/site-packages/Bio/File.py", line 120, in as_handle
    with open(handleish, mode, **kwargs) as fp:
FileNotFoundError: [Errno 2] No such file or directory: '/home/katebrich/Documents/diplomka/datasets/pipeline_test/FASTA/3ldkA.fasta'
2020-08-19 17:47:28,419 [ERROR] compute_feature.py(line 28) Error while processing 2amb A: [Errno 2] No such file or directory: '/home/katebrich/Documents/diplomka/datasets/pipeline_test/FASTA/2ambA.fasta'
Traceback (most recent call last):
  File "./pythonScripts/compute_feature.py", line 19, in __compute_feature
    feat_vals = get_feature(name_of_feature, input_dir, pdb_id, chain_id)
  File "/home/katebrich/Documents/diplomka/GitHub/pythonScripts/features.py", line 21, in get_feature
    return get_pKa_COOH(data_dir, pdb_id, chain_id)
  File "/home/katebrich/Documents/diplomka/GitHub/pythonScripts/features.py", line 65, in get_pKa_COOH
    return get_AA_properties(pKa_COOH, data_dir, pdb_id, chain_id)
  File "/home/katebrich/Documents/diplomka/GitHub/pythonScripts/features.py", line 275, in get_AA_properties
    seq = list(SeqIO.parse(fasta_file, "fasta"))[0]
  File "/home/katebrich/anaconda3/lib/python3.7/site-packages/Bio/SeqIO/FastaIO.py", line 178, in FastaIterator
    with as_handle(handle, "rU") as handle:
  File "/home/katebrich/anaconda3/lib/python3.7/contextlib.py", line 112, in __enter__
    return next(self.gen)
  File "/home/katebrich/anaconda3/lib/python3.7/site-packages/Bio/File.py", line 120, in as_handle
    with open(handleish, mode, **kwargs) as fp:
FileNotFoundError: [Errno 2] No such file or directory: '/home/katebrich/Documents/diplomka/datasets/pipeline_test/FASTA/2ambA.fasta'
2020-08-19 17:47:28,419 [ERROR] compute_feature.py(line 36) 5/8: 1exa A NOT PROCESSED !
2020-08-19 17:47:28,420 [ERROR] compute_feature.py(line 36) 6/8: 1qhi A NOT PROCESSED !
2020-08-19 17:47:28,420 [ERROR] compute_feature.py(line 36) 7/8: 3ldk A NOT PROCESSED !
2020-08-19 17:47:28,420 [ERROR] compute_feature.py(line 36) 8/8: 2amb A NOT PROCESSED !
2020-08-19 17:47:28,420 [WARNING] compute_feature.py(line 102) Computing feature pKa_COOH finished: Some structures were not processed successfully: 
 XXXX X
2g46 A
148l E
1igy B
1exa A
1qhi A
3ldk A
2amb A
2020-08-19 17:47:28,749 [INFO] compute_feature.py(line 81) Computing feature pKa_NH3 started...
2020-08-19 17:47:28,759 [ERROR] compute_feature.py(line 28) Error while processing XXXX X: [Errno 2] No such file or directory: '/home/katebrich/Documents/diplomka/datasets/pipeline_test/FASTA/XXXXX.fasta'
Traceback (most recent call last):
  File "./pythonScripts/compute_feature.py", line 19, in __compute_feature
    feat_vals = get_feature(name_of_feature, input_dir, pdb_id, chain_id)
  File "/home/katebrich/Documents/diplomka/GitHub/pythonScripts/features.py", line 23, in get_feature
    return get_pKa_NH3(data_dir, pdb_id, chain_id)
  File "/home/katebrich/Documents/diplomka/GitHub/pythonScripts/features.py", line 68, in get_pKa_NH3
    return get_AA_properties(pKa_NH3, data_dir, pdb_id, chain_id)
  File "/home/katebrich/Documents/diplomka/GitHub/pythonScripts/features.py", line 275, in get_AA_properties
    seq = list(SeqIO.parse(fasta_file, "fasta"))[0]
  File "/home/katebrich/anaconda3/lib/python3.7/site-packages/Bio/SeqIO/FastaIO.py", line 178, in FastaIterator
    with as_handle(handle, "rU") as handle:
  File "/home/katebrich/anaconda3/lib/python3.7/contextlib.py", line 112, in __enter__
    return next(self.gen)
  File "/home/katebrich/anaconda3/lib/python3.7/site-packages/Bio/File.py", line 120, in as_handle
    with open(handleish, mode, **kwargs) as fp:
FileNotFoundError: [Errno 2] No such file or directory: '/home/katebrich/Documents/diplomka/datasets/pipeline_test/FASTA/XXXXX.fasta'
2020-08-19 17:47:28,760 [ERROR] compute_feature.py(line 28) Error while processing 2g46 A: [Errno 2] No such file or directory: '/home/katebrich/Documents/diplomka/datasets/pipeline_test/FASTA/2g46A.fasta'
Traceback (most recent call last):
  File "./pythonScripts/compute_feature.py", line 19, in __compute_feature
    feat_vals = get_feature(name_of_feature, input_dir, pdb_id, chain_id)
  File "/home/katebrich/Documents/diplomka/GitHub/pythonScripts/features.py", line 23, in get_feature
    return get_pKa_NH3(data_dir, pdb_id, chain_id)
  File "/home/katebrich/Documents/diplomka/GitHub/pythonScripts/features.py", line 68, in get_pKa_NH3
    return get_AA_properties(pKa_NH3, data_dir, pdb_id, chain_id)
  File "/home/katebrich/Documents/diplomka/GitHub/pythonScripts/features.py", line 275, in get_AA_properties
    seq = list(SeqIO.parse(fasta_file, "fasta"))[0]
  File "/home/katebrich/anaconda3/lib/python3.7/site-packages/Bio/SeqIO/FastaIO.py", line 178, in FastaIterator
    with as_handle(handle, "rU") as handle:
  File "/home/katebrich/anaconda3/lib/python3.7/contextlib.py", line 112, in __enter__
    return next(self.gen)
  File "/home/katebrich/anaconda3/lib/python3.7/site-packages/Bio/File.py", line 120, in as_handle
    with open(handleish, mode, **kwargs) as fp:
FileNotFoundError: [Errno 2] No such file or directory: '/home/katebrich/Documents/diplomka/datasets/pipeline_test/FASTA/2g46A.fasta'
2020-08-19 17:47:28,761 [ERROR] compute_feature.py(line 36) 2/8: 2g46 A NOT PROCESSED !
2020-08-19 17:47:28,760 [ERROR] compute_feature.py(line 28) Error while processing 148l E: [Errno 2] No such file or directory: '/home/katebrich/Documents/diplomka/datasets/pipeline_test/FASTA/148lE.fasta'
Traceback (most recent call last):
  File "./pythonScripts/compute_feature.py", line 19, in __compute_feature
    feat_vals = get_feature(name_of_feature, input_dir, pdb_id, chain_id)
  File "/home/katebrich/Documents/diplomka/GitHub/pythonScripts/features.py", line 23, in get_feature
    return get_pKa_NH3(data_dir, pdb_id, chain_id)
  File "/home/katebrich/Documents/diplomka/GitHub/pythonScripts/features.py", line 68, in get_pKa_NH3
    return get_AA_properties(pKa_NH3, data_dir, pdb_id, chain_id)
  File "/home/katebrich/Documents/diplomka/GitHub/pythonScripts/features.py", line 275, in get_AA_properties
    seq = list(SeqIO.parse(fasta_file, "fasta"))[0]
  File "/home/katebrich/anaconda3/lib/python3.7/site-packages/Bio/SeqIO/FastaIO.py", line 178, in FastaIterator
    with as_handle(handle, "rU") as handle:
  File "/home/katebrich/anaconda3/lib/python3.7/contextlib.py", line 112, in __enter__
    return next(self.gen)
  File "/home/katebrich/anaconda3/lib/python3.7/site-packages/Bio/File.py", line 120, in as_handle
    with open(handleish, mode, **kwargs) as fp:
FileNotFoundError: [Errno 2] No such file or directory: '/home/katebrich/Documents/diplomka/datasets/pipeline_test/FASTA/148lE.fasta'
2020-08-19 17:47:28,761 [ERROR] compute_feature.py(line 36) 1/8: XXXX X NOT PROCESSED !
2020-08-19 17:47:28,760 [ERROR] compute_feature.py(line 28) Error while processing 1igy B: [Errno 2] No such file or directory: '/home/katebrich/Documents/diplomka/datasets/pipeline_test/FASTA/1igyB.fasta'
Traceback (most recent call last):
  File "./pythonScripts/compute_feature.py", line 19, in __compute_feature
    feat_vals = get_feature(name_of_feature, input_dir, pdb_id, chain_id)
  File "/home/katebrich/Documents/diplomka/GitHub/pythonScripts/features.py", line 23, in get_feature
    return get_pKa_NH3(data_dir, pdb_id, chain_id)
  File "/home/katebrich/Documents/diplomka/GitHub/pythonScripts/features.py", line 68, in get_pKa_NH3
    return get_AA_properties(pKa_NH3, data_dir, pdb_id, chain_id)
  File "/home/katebrich/Documents/diplomka/GitHub/pythonScripts/features.py", line 275, in get_AA_properties
    seq = list(SeqIO.parse(fasta_file, "fasta"))[0]
  File "/home/katebrich/anaconda3/lib/python3.7/site-packages/Bio/SeqIO/FastaIO.py", line 178, in FastaIterator
    with as_handle(handle, "rU") as handle:
  File "/home/katebrich/anaconda3/lib/python3.7/contextlib.py", line 112, in __enter__
    return next(self.gen)
  File "/home/katebrich/anaconda3/lib/python3.7/site-packages/Bio/File.py", line 120, in as_handle
    with open(handleish, mode, **kwargs) as fp:
FileNotFoundError: [Errno 2] No such file or directory: '/home/katebrich/Documents/diplomka/datasets/pipeline_test/FASTA/1igyB.fasta'
2020-08-19 17:47:28,761 [ERROR] compute_feature.py(line 28) Error while processing 1exa A: [Errno 2] No such file or directory: '/home/katebrich/Documents/diplomka/datasets/pipeline_test/FASTA/1exaA.fasta'
Traceback (most recent call last):
  File "./pythonScripts/compute_feature.py", line 19, in __compute_feature
    feat_vals = get_feature(name_of_feature, input_dir, pdb_id, chain_id)
  File "/home/katebrich/Documents/diplomka/GitHub/pythonScripts/features.py", line 23, in get_feature
    return get_pKa_NH3(data_dir, pdb_id, chain_id)
  File "/home/katebrich/Documents/diplomka/GitHub/pythonScripts/features.py", line 68, in get_pKa_NH3
    return get_AA_properties(pKa_NH3, data_dir, pdb_id, chain_id)
  File "/home/katebrich/Documents/diplomka/GitHub/pythonScripts/features.py", line 275, in get_AA_properties
    seq = list(SeqIO.parse(fasta_file, "fasta"))[0]
  File "/home/katebrich/anaconda3/lib/python3.7/site-packages/Bio/SeqIO/FastaIO.py", line 178, in FastaIterator
    with as_handle(handle, "rU") as handle:
  File "/home/katebrich/anaconda3/lib/python3.7/contextlib.py", line 112, in __enter__
    return next(self.gen)
  File "/home/katebrich/anaconda3/lib/python3.7/site-packages/Bio/File.py", line 120, in as_handle
    with open(handleish, mode, **kwargs) as fp:
FileNotFoundError: [Errno 2] No such file or directory: '/home/katebrich/Documents/diplomka/datasets/pipeline_test/FASTA/1exaA.fasta'
2020-08-19 17:47:28,762 [ERROR] compute_feature.py(line 36) 3/8: 148l E NOT PROCESSED !
2020-08-19 17:47:28,762 [ERROR] compute_feature.py(line 36) 5/8: 1exa A NOT PROCESSED !
2020-08-19 17:47:28,762 [ERROR] compute_feature.py(line 36) 4/8: 1igy B NOT PROCESSED !
2020-08-19 17:47:28,762 [ERROR] compute_feature.py(line 28) Error while processing 1qhi A: [Errno 2] No such file or directory: '/home/katebrich/Documents/diplomka/datasets/pipeline_test/FASTA/1qhiA.fasta'
Traceback (most recent call last):
  File "./pythonScripts/compute_feature.py", line 19, in __compute_feature
    feat_vals = get_feature(name_of_feature, input_dir, pdb_id, chain_id)
  File "/home/katebrich/Documents/diplomka/GitHub/pythonScripts/features.py", line 23, in get_feature
    return get_pKa_NH3(data_dir, pdb_id, chain_id)
  File "/home/katebrich/Documents/diplomka/GitHub/pythonScripts/features.py", line 68, in get_pKa_NH3
    return get_AA_properties(pKa_NH3, data_dir, pdb_id, chain_id)
  File "/home/katebrich/Documents/diplomka/GitHub/pythonScripts/features.py", line 275, in get_AA_properties
    seq = list(SeqIO.parse(fasta_file, "fasta"))[0]
  File "/home/katebrich/anaconda3/lib/python3.7/site-packages/Bio/SeqIO/FastaIO.py", line 178, in FastaIterator
    with as_handle(handle, "rU") as handle:
  File "/home/katebrich/anaconda3/lib/python3.7/contextlib.py", line 112, in __enter__
    return next(self.gen)
  File "/home/katebrich/anaconda3/lib/python3.7/site-packages/Bio/File.py", line 120, in as_handle
    with open(handleish, mode, **kwargs) as fp:
FileNotFoundError: [Errno 2] No such file or directory: '/home/katebrich/Documents/diplomka/datasets/pipeline_test/FASTA/1qhiA.fasta'
2020-08-19 17:47:28,762 [ERROR] compute_feature.py(line 28) Error while processing 3ldk A: [Errno 2] No such file or directory: '/home/katebrich/Documents/diplomka/datasets/pipeline_test/FASTA/3ldkA.fasta'
Traceback (most recent call last):
  File "./pythonScripts/compute_feature.py", line 19, in __compute_feature
    feat_vals = get_feature(name_of_feature, input_dir, pdb_id, chain_id)
  File "/home/katebrich/Documents/diplomka/GitHub/pythonScripts/features.py", line 23, in get_feature
    return get_pKa_NH3(data_dir, pdb_id, chain_id)
  File "/home/katebrich/Documents/diplomka/GitHub/pythonScripts/features.py", line 68, in get_pKa_NH3
    return get_AA_properties(pKa_NH3, data_dir, pdb_id, chain_id)
  File "/home/katebrich/Documents/diplomka/GitHub/pythonScripts/features.py", line 275, in get_AA_properties
    seq = list(SeqIO.parse(fasta_file, "fasta"))[0]
  File "/home/katebrich/anaconda3/lib/python3.7/site-packages/Bio/SeqIO/FastaIO.py", line 178, in FastaIterator
    with as_handle(handle, "rU") as handle:
  File "/home/katebrich/anaconda3/lib/python3.7/contextlib.py", line 112, in __enter__
    return next(self.gen)
  File "/home/katebrich/anaconda3/lib/python3.7/site-packages/Bio/File.py", line 120, in as_handle
    with open(handleish, mode, **kwargs) as fp:
FileNotFoundError: [Errno 2] No such file or directory: '/home/katebrich/Documents/diplomka/datasets/pipeline_test/FASTA/3ldkA.fasta'
2020-08-19 17:47:28,763 [ERROR] compute_feature.py(line 28) Error while processing 2amb A: [Errno 2] No such file or directory: '/home/katebrich/Documents/diplomka/datasets/pipeline_test/FASTA/2ambA.fasta'
Traceback (most recent call last):
  File "./pythonScripts/compute_feature.py", line 19, in __compute_feature
    feat_vals = get_feature(name_of_feature, input_dir, pdb_id, chain_id)
  File "/home/katebrich/Documents/diplomka/GitHub/pythonScripts/features.py", line 23, in get_feature
    return get_pKa_NH3(data_dir, pdb_id, chain_id)
  File "/home/katebrich/Documents/diplomka/GitHub/pythonScripts/features.py", line 68, in get_pKa_NH3
    return get_AA_properties(pKa_NH3, data_dir, pdb_id, chain_id)
  File "/home/katebrich/Documents/diplomka/GitHub/pythonScripts/features.py", line 275, in get_AA_properties
    seq = list(SeqIO.parse(fasta_file, "fasta"))[0]
  File "/home/katebrich/anaconda3/lib/python3.7/site-packages/Bio/SeqIO/FastaIO.py", line 178, in FastaIterator
    with as_handle(handle, "rU") as handle:
  File "/home/katebrich/anaconda3/lib/python3.7/contextlib.py", line 112, in __enter__
    return next(self.gen)
  File "/home/katebrich/anaconda3/lib/python3.7/site-packages/Bio/File.py", line 120, in as_handle
    with open(handleish, mode, **kwargs) as fp:
FileNotFoundError: [Errno 2] No such file or directory: '/home/katebrich/Documents/diplomka/datasets/pipeline_test/FASTA/2ambA.fasta'
2020-08-19 17:47:28,763 [ERROR] compute_feature.py(line 36) 6/8: 1qhi A NOT PROCESSED !
2020-08-19 17:47:28,763 [ERROR] compute_feature.py(line 36) 7/8: 3ldk A NOT PROCESSED !
2020-08-19 17:47:28,763 [ERROR] compute_feature.py(line 36) 8/8: 2amb A NOT PROCESSED !
2020-08-19 17:47:28,764 [WARNING] compute_feature.py(line 102) Computing feature pKa_NH3 finished: Some structures were not processed successfully: 
 XXXX X
2g46 A
148l E
1igy B
1exa A
1qhi A
3ldk A
2amb A
2020-08-19 17:47:29,086 [INFO] compute_feature.py(line 81) Computing feature molecular_weight started...
2020-08-19 17:47:29,105 [ERROR] compute_feature.py(line 28) Error while processing XXXX X: [Errno 2] No such file or directory: '/home/katebrich/Documents/diplomka/datasets/pipeline_test/FASTA/XXXXX.fasta'
Traceback (most recent call last):
  File "./pythonScripts/compute_feature.py", line 19, in __compute_feature
    feat_vals = get_feature(name_of_feature, input_dir, pdb_id, chain_id)
  File "/home/katebrich/Documents/diplomka/GitHub/pythonScripts/features.py", line 25, in get_feature
    return get_molecular_weight(data_dir, pdb_id, chain_id)
  File "/home/katebrich/Documents/diplomka/GitHub/pythonScripts/features.py", line 62, in get_molecular_weight
    return get_AA_properties(molecular_weight, data_dir, pdb_id, chain_id)
  File "/home/katebrich/Documents/diplomka/GitHub/pythonScripts/features.py", line 275, in get_AA_properties
    seq = list(SeqIO.parse(fasta_file, "fasta"))[0]
  File "/home/katebrich/anaconda3/lib/python3.7/site-packages/Bio/SeqIO/FastaIO.py", line 178, in FastaIterator
    with as_handle(handle, "rU") as handle:
  File "/home/katebrich/anaconda3/lib/python3.7/contextlib.py", line 112, in __enter__
    return next(self.gen)
  File "/home/katebrich/anaconda3/lib/python3.7/site-packages/Bio/File.py", line 120, in as_handle
    with open(handleish, mode, **kwargs) as fp:
FileNotFoundError: [Errno 2] No such file or directory: '/home/katebrich/Documents/diplomka/datasets/pipeline_test/FASTA/XXXXX.fasta'
2020-08-19 17:47:29,105 [ERROR] compute_feature.py(line 28) Error while processing 2g46 A: [Errno 2] No such file or directory: '/home/katebrich/Documents/diplomka/datasets/pipeline_test/FASTA/2g46A.fasta'
Traceback (most recent call last):
  File "./pythonScripts/compute_feature.py", line 19, in __compute_feature
    feat_vals = get_feature(name_of_feature, input_dir, pdb_id, chain_id)
  File "/home/katebrich/Documents/diplomka/GitHub/pythonScripts/features.py", line 25, in get_feature
    return get_molecular_weight(data_dir, pdb_id, chain_id)
  File "/home/katebrich/Documents/diplomka/GitHub/pythonScripts/features.py", line 62, in get_molecular_weight
    return get_AA_properties(molecular_weight, data_dir, pdb_id, chain_id)
  File "/home/katebrich/Documents/diplomka/GitHub/pythonScripts/features.py", line 275, in get_AA_properties
    seq = list(SeqIO.parse(fasta_file, "fasta"))[0]
  File "/home/katebrich/anaconda3/lib/python3.7/site-packages/Bio/SeqIO/FastaIO.py", line 178, in FastaIterator
    with as_handle(handle, "rU") as handle:
  File "/home/katebrich/anaconda3/lib/python3.7/contextlib.py", line 112, in __enter__
    return next(self.gen)
  File "/home/katebrich/anaconda3/lib/python3.7/site-packages/Bio/File.py", line 120, in as_handle
    with open(handleish, mode, **kwargs) as fp:
FileNotFoundError: [Errno 2] No such file or directory: '/home/katebrich/Documents/diplomka/datasets/pipeline_test/FASTA/2g46A.fasta'
2020-08-19 17:47:29,106 [ERROR] compute_feature.py(line 28) Error while processing 148l E: [Errno 2] No such file or directory: '/home/katebrich/Documents/diplomka/datasets/pipeline_test/FASTA/148lE.fasta'
Traceback (most recent call last):
  File "./pythonScripts/compute_feature.py", line 19, in __compute_feature
    feat_vals = get_feature(name_of_feature, input_dir, pdb_id, chain_id)
  File "/home/katebrich/Documents/diplomka/GitHub/pythonScripts/features.py", line 25, in get_feature
    return get_molecular_weight(data_dir, pdb_id, chain_id)
  File "/home/katebrich/Documents/diplomka/GitHub/pythonScripts/features.py", line 62, in get_molecular_weight
    return get_AA_properties(molecular_weight, data_dir, pdb_id, chain_id)
  File "/home/katebrich/Documents/diplomka/GitHub/pythonScripts/features.py", line 275, in get_AA_properties
    seq = list(SeqIO.parse(fasta_file, "fasta"))[0]
  File "/home/katebrich/anaconda3/lib/python3.7/site-packages/Bio/SeqIO/FastaIO.py", line 178, in FastaIterator
    with as_handle(handle, "rU") as handle:
  File "/home/katebrich/anaconda3/lib/python3.7/contextlib.py", line 112, in __enter__
    return next(self.gen)
  File "/home/katebrich/anaconda3/lib/python3.7/site-packages/Bio/File.py", line 120, in as_handle
    with open(handleish, mode, **kwargs) as fp:
FileNotFoundError: [Errno 2] No such file or directory: '/home/katebrich/Documents/diplomka/datasets/pipeline_test/FASTA/148lE.fasta'
2020-08-19 17:47:29,106 [ERROR] compute_feature.py(line 28) Error while processing 1igy B: [Errno 2] No such file or directory: '/home/katebrich/Documents/diplomka/datasets/pipeline_test/FASTA/1igyB.fasta'
Traceback (most recent call last):
  File "./pythonScripts/compute_feature.py", line 19, in __compute_feature
    feat_vals = get_feature(name_of_feature, input_dir, pdb_id, chain_id)
  File "/home/katebrich/Documents/diplomka/GitHub/pythonScripts/features.py", line 25, in get_feature
    return get_molecular_weight(data_dir, pdb_id, chain_id)
  File "/home/katebrich/Documents/diplomka/GitHub/pythonScripts/features.py", line 62, in get_molecular_weight
    return get_AA_properties(molecular_weight, data_dir, pdb_id, chain_id)
  File "/home/katebrich/Documents/diplomka/GitHub/pythonScripts/features.py", line 275, in get_AA_properties
    seq = list(SeqIO.parse(fasta_file, "fasta"))[0]
  File "/home/katebrich/anaconda3/lib/python3.7/site-packages/Bio/SeqIO/FastaIO.py", line 178, in FastaIterator
    with as_handle(handle, "rU") as handle:
  File "/home/katebrich/anaconda3/lib/python3.7/contextlib.py", line 112, in __enter__
    return next(self.gen)
  File "/home/katebrich/anaconda3/lib/python3.7/site-packages/Bio/File.py", line 120, in as_handle
    with open(handleish, mode, **kwargs) as fp:
FileNotFoundError: [Errno 2] No such file or directory: '/home/katebrich/Documents/diplomka/datasets/pipeline_test/FASTA/1igyB.fasta'
2020-08-19 17:47:29,107 [ERROR] compute_feature.py(line 36) 1/8: XXXX X NOT PROCESSED !
2020-08-19 17:47:29,107 [ERROR] compute_feature.py(line 36) 2/8: 2g46 A NOT PROCESSED !
2020-08-19 17:47:29,107 [ERROR] compute_feature.py(line 36) 3/8: 148l E NOT PROCESSED !
2020-08-19 17:47:29,107 [ERROR] compute_feature.py(line 36) 4/8: 1igy B NOT PROCESSED !
2020-08-19 17:47:29,108 [ERROR] compute_feature.py(line 28) Error while processing 1exa A: [Errno 2] No such file or directory: '/home/katebrich/Documents/diplomka/datasets/pipeline_test/FASTA/1exaA.fasta'
Traceback (most recent call last):
  File "./pythonScripts/compute_feature.py", line 19, in __compute_feature
    feat_vals = get_feature(name_of_feature, input_dir, pdb_id, chain_id)
  File "/home/katebrich/Documents/diplomka/GitHub/pythonScripts/features.py", line 25, in get_feature
    return get_molecular_weight(data_dir, pdb_id, chain_id)
  File "/home/katebrich/Documents/diplomka/GitHub/pythonScripts/features.py", line 62, in get_molecular_weight
    return get_AA_properties(molecular_weight, data_dir, pdb_id, chain_id)
  File "/home/katebrich/Documents/diplomka/GitHub/pythonScripts/features.py", line 275, in get_AA_properties
    seq = list(SeqIO.parse(fasta_file, "fasta"))[0]
  File "/home/katebrich/anaconda3/lib/python3.7/site-packages/Bio/SeqIO/FastaIO.py", line 178, in FastaIterator
    with as_handle(handle, "rU") as handle:
  File "/home/katebrich/anaconda3/lib/python3.7/contextlib.py", line 112, in __enter__
    return next(self.gen)
  File "/home/katebrich/anaconda3/lib/python3.7/site-packages/Bio/File.py", line 120, in as_handle
    with open(handleish, mode, **kwargs) as fp:
FileNotFoundError: [Errno 2] No such file or directory: '/home/katebrich/Documents/diplomka/datasets/pipeline_test/FASTA/1exaA.fasta'
2020-08-19 17:47:29,108 [ERROR] compute_feature.py(line 28) Error while processing 1qhi A: [Errno 2] No such file or directory: '/home/katebrich/Documents/diplomka/datasets/pipeline_test/FASTA/1qhiA.fasta'
Traceback (most recent call last):
  File "./pythonScripts/compute_feature.py", line 19, in __compute_feature
    feat_vals = get_feature(name_of_feature, input_dir, pdb_id, chain_id)
  File "/home/katebrich/Documents/diplomka/GitHub/pythonScripts/features.py", line 25, in get_feature
    return get_molecular_weight(data_dir, pdb_id, chain_id)
  File "/home/katebrich/Documents/diplomka/GitHub/pythonScripts/features.py", line 62, in get_molecular_weight
    return get_AA_properties(molecular_weight, data_dir, pdb_id, chain_id)
  File "/home/katebrich/Documents/diplomka/GitHub/pythonScripts/features.py", line 275, in get_AA_properties
    seq = list(SeqIO.parse(fasta_file, "fasta"))[0]
  File "/home/katebrich/anaconda3/lib/python3.7/site-packages/Bio/SeqIO/FastaIO.py", line 178, in FastaIterator
    with as_handle(handle, "rU") as handle:
  File "/home/katebrich/anaconda3/lib/python3.7/contextlib.py", line 112, in __enter__
    return next(self.gen)
  File "/home/katebrich/anaconda3/lib/python3.7/site-packages/Bio/File.py", line 120, in as_handle
    with open(handleish, mode, **kwargs) as fp:
FileNotFoundError: [Errno 2] No such file or directory: '/home/katebrich/Documents/diplomka/datasets/pipeline_test/FASTA/1qhiA.fasta'
2020-08-19 17:47:29,108 [ERROR] compute_feature.py(line 28) Error while processing 3ldk A: [Errno 2] No such file or directory: '/home/katebrich/Documents/diplomka/datasets/pipeline_test/FASTA/3ldkA.fasta'
Traceback (most recent call last):
  File "./pythonScripts/compute_feature.py", line 19, in __compute_feature
    feat_vals = get_feature(name_of_feature, input_dir, pdb_id, chain_id)
  File "/home/katebrich/Documents/diplomka/GitHub/pythonScripts/features.py", line 25, in get_feature
    return get_molecular_weight(data_dir, pdb_id, chain_id)
  File "/home/katebrich/Documents/diplomka/GitHub/pythonScripts/features.py", line 62, in get_molecular_weight
    return get_AA_properties(molecular_weight, data_dir, pdb_id, chain_id)
  File "/home/katebrich/Documents/diplomka/GitHub/pythonScripts/features.py", line 275, in get_AA_properties
    seq = list(SeqIO.parse(fasta_file, "fasta"))[0]
  File "/home/katebrich/anaconda3/lib/python3.7/site-packages/Bio/SeqIO/FastaIO.py", line 178, in FastaIterator
    with as_handle(handle, "rU") as handle:
  File "/home/katebrich/anaconda3/lib/python3.7/contextlib.py", line 112, in __enter__
    return next(self.gen)
  File "/home/katebrich/anaconda3/lib/python3.7/site-packages/Bio/File.py", line 120, in as_handle
    with open(handleish, mode, **kwargs) as fp:
FileNotFoundError: [Errno 2] No such file or directory: '/home/katebrich/Documents/diplomka/datasets/pipeline_test/FASTA/3ldkA.fasta'
2020-08-19 17:47:29,108 [ERROR] compute_feature.py(line 28) Error while processing 2amb A: [Errno 2] No such file or directory: '/home/katebrich/Documents/diplomka/datasets/pipeline_test/FASTA/2ambA.fasta'
Traceback (most recent call last):
  File "./pythonScripts/compute_feature.py", line 19, in __compute_feature
    feat_vals = get_feature(name_of_feature, input_dir, pdb_id, chain_id)
  File "/home/katebrich/Documents/diplomka/GitHub/pythonScripts/features.py", line 25, in get_feature
    return get_molecular_weight(data_dir, pdb_id, chain_id)
  File "/home/katebrich/Documents/diplomka/GitHub/pythonScripts/features.py", line 62, in get_molecular_weight
    return get_AA_properties(molecular_weight, data_dir, pdb_id, chain_id)
  File "/home/katebrich/Documents/diplomka/GitHub/pythonScripts/features.py", line 275, in get_AA_properties
    seq = list(SeqIO.parse(fasta_file, "fasta"))[0]
  File "/home/katebrich/anaconda3/lib/python3.7/site-packages/Bio/SeqIO/FastaIO.py", line 178, in FastaIterator
    with as_handle(handle, "rU") as handle:
  File "/home/katebrich/anaconda3/lib/python3.7/contextlib.py", line 112, in __enter__
    return next(self.gen)
  File "/home/katebrich/anaconda3/lib/python3.7/site-packages/Bio/File.py", line 120, in as_handle
    with open(handleish, mode, **kwargs) as fp:
FileNotFoundError: [Errno 2] No such file or directory: '/home/katebrich/Documents/diplomka/datasets/pipeline_test/FASTA/2ambA.fasta'
2020-08-19 17:47:29,108 [ERROR] compute_feature.py(line 36) 5/8: 1exa A NOT PROCESSED !
2020-08-19 17:47:29,109 [ERROR] compute_feature.py(line 36) 6/8: 1qhi A NOT PROCESSED !
2020-08-19 17:47:29,109 [ERROR] compute_feature.py(line 36) 7/8: 3ldk A NOT PROCESSED !
2020-08-19 17:47:29,109 [ERROR] compute_feature.py(line 36) 8/8: 2amb A NOT PROCESSED !
2020-08-19 17:47:29,109 [WARNING] compute_feature.py(line 102) Computing feature molecular_weight finished: Some structures were not processed successfully: 
 XXXX X
2g46 A
148l E
1igy B
1exa A
1qhi A
3ldk A
2amb A
2020-08-19 17:47:29,443 [INFO] compute_feature.py(line 81) Computing feature unp_variants started...
2020-08-19 17:47:30,040 [ERROR] compute_feature.py(line 28) Error while processing XXXX X: HTTP Error 404: Not Found
Traceback (most recent call last):
  File "./pythonScripts/compute_feature.py", line 19, in __compute_feature
    feat_vals = get_feature(name_of_feature, input_dir, pdb_id, chain_id)
  File "/home/katebrich/Documents/diplomka/GitHub/pythonScripts/features.py", line 13, in get_feature
    return get_variants(data_dir, pdb_id, chain_id)
  File "/home/katebrich/Documents/diplomka/GitHub/pythonScripts/features.py", line 154, in get_variants
    entities = get_uniprot_entity(pdb_id, chain_id)
  File "/home/katebrich/Documents/diplomka/GitHub/pythonScripts/helper.py", line 12, in get_uniprot_entity
    parsedResponse = restAPI_get_json(url)
  File "/home/katebrich/Documents/diplomka/GitHub/pythonScripts/helper.py", line 47, in restAPI_get_json
    return json.loads(restAPI_get(url))
  File "/home/katebrich/Documents/diplomka/GitHub/pythonScripts/helper.py", line 41, in restAPI_get
    with urllib.request.urlopen(req) as f:
  File "/home/katebrich/anaconda3/lib/python3.7/urllib/request.py", line 222, in urlopen
    return opener.open(url, data, timeout)
  File "/home/katebrich/anaconda3/lib/python3.7/urllib/request.py", line 531, in open
    response = meth(req, response)
  File "/home/katebrich/anaconda3/lib/python3.7/urllib/request.py", line 641, in http_response
    'http', request, response, code, msg, hdrs)
  File "/home/katebrich/anaconda3/lib/python3.7/urllib/request.py", line 569, in error
    return self._call_chain(*args)
  File "/home/katebrich/anaconda3/lib/python3.7/urllib/request.py", line 503, in _call_chain
    result = func(*args)
  File "/home/katebrich/anaconda3/lib/python3.7/urllib/request.py", line 649, in http_error_default
    raise HTTPError(req.full_url, code, msg, hdrs, fp)
urllib.error.HTTPError: HTTP Error 404: Not Found
2020-08-19 17:47:30,072 [ERROR] compute_feature.py(line 36) 1/8: XXXX X NOT PROCESSED !
2020-08-19 17:48:54,525 [INFO] download_dataset.py(line 145) Downloading structures from /home/katebrich/Documents/diplomka/datasets/test.txt to /home/katebrich/Documents/diplomka/datasets/pipeline_test started...
2020-08-19 17:48:54,981 [ERROR] download_dataset.py(line 91) Error while downloading XXXX X: HTTP Error 404: Not Found
Traceback (most recent call last):
  File "./pythonScripts/download_dataset.py", line 83, in download_structure
    get_PDB(temp_file, output_PDB, pdb_id, chain_ids, ligands_filter)
  File "./pythonScripts/download_dataset.py", line 33, in get_PDB
    response = restAPI_get(url)
  File "/home/katebrich/Documents/diplomka/GitHub/pythonScripts/helper.py", line 41, in restAPI_get
    with urllib.request.urlopen(req) as f:
  File "/home/katebrich/anaconda3/lib/python3.7/urllib/request.py", line 222, in urlopen
    return opener.open(url, data, timeout)
  File "/home/katebrich/anaconda3/lib/python3.7/urllib/request.py", line 531, in open
    response = meth(req, response)
  File "/home/katebrich/anaconda3/lib/python3.7/urllib/request.py", line 641, in http_response
    'http', request, response, code, msg, hdrs)
  File "/home/katebrich/anaconda3/lib/python3.7/urllib/request.py", line 569, in error
    return self._call_chain(*args)
  File "/home/katebrich/anaconda3/lib/python3.7/urllib/request.py", line 503, in _call_chain
    result = func(*args)
  File "/home/katebrich/anaconda3/lib/python3.7/urllib/request.py", line 649, in http_error_default
    raise HTTPError(req.full_url, code, msg, hdrs, fp)
urllib.error.HTTPError: HTTP Error 404: Not Found
2020-08-19 17:48:54,985 [ERROR] download_dataset.py(line 101) 1/8: XXXX X NOT DOWNLOADED !
2020-08-19 17:49:15,229 [WARNING] download_dataset.py(line 166) Downloading structures finished: Some structures were not downloaded successfully: 
 XXXX X
2020-08-19 17:49:15,430 [INFO] create_mappings_cache.py(line 69) Creating mapping cache started...
2020-08-19 17:49:15,763 [ERROR] create_mappings_cache.py(line 25) Error while processing XXXX X: HTTP Error 404: Not Found
Traceback (most recent call last):
  File "./pythonScripts/create_mappings_cache.py", line 17, in create_mappings_cache
    mappings = res_mappings_author_to_pdbe(pdb_id, chain_id)
  File "/home/katebrich/Documents/diplomka/GitHub/pythonScripts/helper.py", line 112, in res_mappings_author_to_pdbe
    response = restAPI_get_json(f"https://www.ebi.ac.uk/pdbe/api/pdb/entry/residue_listing/{pdb_id}/chain/{chain_id}")
  File "/home/katebrich/Documents/diplomka/GitHub/pythonScripts/helper.py", line 47, in restAPI_get_json
    return json.loads(restAPI_get(url))
  File "/home/katebrich/Documents/diplomka/GitHub/pythonScripts/helper.py", line 41, in restAPI_get
    with urllib.request.urlopen(req) as f:
  File "/home/katebrich/anaconda3/lib/python3.7/urllib/request.py", line 222, in urlopen
    return opener.open(url, data, timeout)
  File "/home/katebrich/anaconda3/lib/python3.7/urllib/request.py", line 531, in open
    response = meth(req, response)
  File "/home/katebrich/anaconda3/lib/python3.7/urllib/request.py", line 641, in http_response
    'http', request, response, code, msg, hdrs)
  File "/home/katebrich/anaconda3/lib/python3.7/urllib/request.py", line 569, in error
    return self._call_chain(*args)
  File "/home/katebrich/anaconda3/lib/python3.7/urllib/request.py", line 503, in _call_chain
    result = func(*args)
  File "/home/katebrich/anaconda3/lib/python3.7/urllib/request.py", line 649, in http_error_default
    raise HTTPError(req.full_url, code, msg, hdrs, fp)
urllib.error.HTTPError: HTTP Error 404: Not Found
2020-08-19 17:49:15,768 [ERROR] create_mappings_cache.py(line 33) 1/8: XXXX X NOT PROCESSED !
2020-08-19 17:49:17,920 [WARNING] create_mappings_cache.py(line 89) Creating mapping cache finished: Some structures were not processed successfully: 
 XXXX X
2020-08-19 17:49:18,184 [INFO] compute_ligand_binding_sites.py(line 118) Computing ligand binding sites started...
2020-08-19 17:49:18,189 [ERROR] compute_ligand_binding_sites.py(line 26) Error while processing XXXX X: [Errno 2] No such file or directory: '/home/katebrich/Documents/diplomka/datasets/pipeline_test/PDB/XXXXX.pdb'
Traceback (most recent call last):
  File "./pythonScripts/compute_ligand_binding_sites.py", line 18, in __get_ligand_binding_site
    lbs = __compute_ligand_binding_sites(pdb_id, chain_id, pdb_path)
  File "./pythonScripts/compute_ligand_binding_sites.py", line 44, in __compute_ligand_binding_sites
    structure = parser.get_structure(pdb_id + chain_id, pdb_file_path)
  File "/home/katebrich/anaconda3/lib/python3.7/site-packages/Bio/PDB/PDBParser.py", line 88, in get_structure
    with as_handle(file, mode="rU") as handle:
  File "/home/katebrich/anaconda3/lib/python3.7/contextlib.py", line 112, in __enter__
    return next(self.gen)
  File "/home/katebrich/anaconda3/lib/python3.7/site-packages/Bio/File.py", line 120, in as_handle
    with open(handleish, mode, **kwargs) as fp:
FileNotFoundError: [Errno 2] No such file or directory: '/home/katebrich/Documents/diplomka/datasets/pipeline_test/PDB/XXXXX.pdb'
2020-08-19 17:49:18,223 [ERROR] compute_ligand_binding_sites.py(line 34) 1/8: XXXX X NOT PROCESSED !
2020-08-19 17:49:23,383 [WARNING] compute_ligand_binding_sites.py(line 138) Computing ligand binding sites finished: Some structures were not processed successfully: 
 XXXX X
2020-08-19 17:49:23,659 [INFO] compute_feature.py(line 81) Computing feature pdbkb_conservation started...
2020-08-19 17:49:23,983 [ERROR] compute_feature.py(line 28) Error while processing XXXX X: HTTP Error 404: Not Found
Traceback (most recent call last):
  File "./pythonScripts/compute_feature.py", line 19, in __compute_feature
    feat_vals = get_feature(name_of_feature, input_dir, pdb_id, chain_id)
  File "/home/katebrich/Documents/diplomka/GitHub/pythonScripts/features.py", line 15, in get_feature
    return get_pdbkb_conservation(data_dir, pdb_id, chain_id)
  File "/home/katebrich/Documents/diplomka/GitHub/pythonScripts/features.py", line 190, in get_pdbkb_conservation
    entities = get_uniprot_entity(pdb_id, chain_id)
  File "/home/katebrich/Documents/diplomka/GitHub/pythonScripts/helper.py", line 12, in get_uniprot_entity
    parsedResponse = restAPI_get_json(url)
  File "/home/katebrich/Documents/diplomka/GitHub/pythonScripts/helper.py", line 47, in restAPI_get_json
    return json.loads(restAPI_get(url))
  File "/home/katebrich/Documents/diplomka/GitHub/pythonScripts/helper.py", line 41, in restAPI_get
    with urllib.request.urlopen(req) as f:
  File "/home/katebrich/anaconda3/lib/python3.7/urllib/request.py", line 222, in urlopen
    return opener.open(url, data, timeout)
  File "/home/katebrich/anaconda3/lib/python3.7/urllib/request.py", line 531, in open
    response = meth(req, response)
  File "/home/katebrich/anaconda3/lib/python3.7/urllib/request.py", line 641, in http_response
    'http', request, response, code, msg, hdrs)
  File "/home/katebrich/anaconda3/lib/python3.7/urllib/request.py", line 569, in error
    return self._call_chain(*args)
  File "/home/katebrich/anaconda3/lib/python3.7/urllib/request.py", line 503, in _call_chain
    result = func(*args)
  File "/home/katebrich/anaconda3/lib/python3.7/urllib/request.py", line 649, in http_error_default
    raise HTTPError(req.full_url, code, msg, hdrs, fp)
urllib.error.HTTPError: HTTP Error 404: Not Found
2020-08-19 17:49:23,988 [ERROR] compute_feature.py(line 36) 1/8: XXXX X NOT PROCESSED !
2020-08-19 17:49:25,238 [ERROR] compute_feature.py(line 28) Error while processing 148l E: list assignment index out of range
Traceback (most recent call last):
  File "./pythonScripts/compute_feature.py", line 19, in __compute_feature
    feat_vals = get_feature(name_of_feature, input_dir, pdb_id, chain_id)
  File "/home/katebrich/Documents/diplomka/GitHub/pythonScripts/features.py", line 15, in get_feature
    return get_pdbkb_conservation(data_dir, pdb_id, chain_id)
  File "/home/katebrich/Documents/diplomka/GitHub/pythonScripts/features.py", line 214, in get_pdbkb_conservation
    feature_vector[feat_begin] = resi["conservation_score"]
IndexError: list assignment index out of range
2020-08-19 17:49:25,238 [ERROR] compute_feature.py(line 36) 2/8: 148l E NOT PROCESSED !
2020-08-19 17:49:25,766 [ERROR] compute_feature.py(line 28) Error while processing 2g46 A: 'int' object is not subscriptable
Traceback (most recent call last):
  File "./pythonScripts/compute_feature.py", line 23, in __compute_feature
    f.write('\n'.join('{} {}'.format(x[0], x[1]) for x in feat_vals))
  File "./pythonScripts/compute_feature.py", line 23, in <genexpr>
    f.write('\n'.join('{} {}'.format(x[0], x[1]) for x in feat_vals))
TypeError: 'int' object is not subscriptable
2020-08-19 17:49:25,766 [ERROR] compute_feature.py(line 36) 3/8: 2g46 A NOT PROCESSED !
2020-08-19 17:49:25,971 [ERROR] compute_feature.py(line 28) Error while processing 1exa A: list assignment index out of range
Traceback (most recent call last):
  File "./pythonScripts/compute_feature.py", line 19, in __compute_feature
    feat_vals = get_feature(name_of_feature, input_dir, pdb_id, chain_id)
  File "/home/katebrich/Documents/diplomka/GitHub/pythonScripts/features.py", line 15, in get_feature
    return get_pdbkb_conservation(data_dir, pdb_id, chain_id)
  File "/home/katebrich/Documents/diplomka/GitHub/pythonScripts/features.py", line 214, in get_pdbkb_conservation
    feature_vector[feat_begin] = resi["conservation_score"]
IndexError: list assignment index out of range
2020-08-19 17:49:25,972 [ERROR] compute_feature.py(line 36) 4/8: 1exa A NOT PROCESSED !
2020-08-19 17:49:27,053 [ERROR] compute_feature.py(line 28) Error while processing 1igy B: list assignment index out of range
Traceback (most recent call last):
  File "./pythonScripts/compute_feature.py", line 19, in __compute_feature
    feat_vals = get_feature(name_of_feature, input_dir, pdb_id, chain_id)
  File "/home/katebrich/Documents/diplomka/GitHub/pythonScripts/features.py", line 15, in get_feature
    return get_pdbkb_conservation(data_dir, pdb_id, chain_id)
  File "/home/katebrich/Documents/diplomka/GitHub/pythonScripts/features.py", line 214, in get_pdbkb_conservation
    feature_vector[feat_begin] = resi["conservation_score"]
IndexError: list assignment index out of range
2020-08-19 17:49:27,054 [ERROR] compute_feature.py(line 36) 5/8: 1igy B NOT PROCESSED !
2020-08-19 17:49:27,532 [ERROR] compute_feature.py(line 28) Error while processing 1qhi A: 'int' object is not subscriptable
Traceback (most recent call last):
  File "./pythonScripts/compute_feature.py", line 23, in __compute_feature
    f.write('\n'.join('{} {}'.format(x[0], x[1]) for x in feat_vals))
  File "./pythonScripts/compute_feature.py", line 23, in <genexpr>
    f.write('\n'.join('{} {}'.format(x[0], x[1]) for x in feat_vals))
TypeError: 'int' object is not subscriptable
2020-08-19 17:49:27,533 [ERROR] compute_feature.py(line 36) 6/8: 1qhi A NOT PROCESSED !
2020-08-19 17:49:28,658 [ERROR] compute_feature.py(line 28) Error while processing 2amb A: list assignment index out of range
Traceback (most recent call last):
  File "./pythonScripts/compute_feature.py", line 19, in __compute_feature
    feat_vals = get_feature(name_of_feature, input_dir, pdb_id, chain_id)
  File "/home/katebrich/Documents/diplomka/GitHub/pythonScripts/features.py", line 15, in get_feature
    return get_pdbkb_conservation(data_dir, pdb_id, chain_id)
  File "/home/katebrich/Documents/diplomka/GitHub/pythonScripts/features.py", line 214, in get_pdbkb_conservation
    feature_vector[feat_begin] = resi["conservation_score"]
IndexError: list assignment index out of range
2020-08-19 17:49:28,659 [ERROR] compute_feature.py(line 36) 7/8: 2amb A NOT PROCESSED !
2020-08-19 17:49:28,775 [ERROR] compute_feature.py(line 28) Error while processing 3ldk A: list assignment index out of range
Traceback (most recent call last):
  File "./pythonScripts/compute_feature.py", line 19, in __compute_feature
    feat_vals = get_feature(name_of_feature, input_dir, pdb_id, chain_id)
  File "/home/katebrich/Documents/diplomka/GitHub/pythonScripts/features.py", line 15, in get_feature
    return get_pdbkb_conservation(data_dir, pdb_id, chain_id)
  File "/home/katebrich/Documents/diplomka/GitHub/pythonScripts/features.py", line 214, in get_pdbkb_conservation
    feature_vector[feat_begin] = resi["conservation_score"]
IndexError: list assignment index out of range
2020-08-19 17:49:28,778 [ERROR] compute_feature.py(line 36) 8/8: 3ldk A NOT PROCESSED !
2020-08-19 17:49:28,778 [WARNING] compute_feature.py(line 102) Computing feature pdbkb_conservation finished: Some structures were not processed successfully: 
 XXXX X
148l E
2g46 A
1exa A
1igy B
1qhi A
2amb A
3ldk A
2020-08-19 17:49:29,583 [INFO] run_analysis.py(line 107) Running analysis started...
2020-08-19 17:49:29,584 [ERROR] run_analysis.py(line 48) Error while processing XXXX X: /home/katebrich/Documents/diplomka/datasets/pipeline_test/lbs/XXXXX.txt not found.
Traceback (most recent call last):
  File "./pythonScripts/run_analysis.py", line 24, in compute_pairs
    lbs = np.genfromtxt(file, delimiter=' ')
  File "/home/katebrich/anaconda3/lib/python3.7/site-packages/numpy/lib/npyio.py", line 1772, in genfromtxt
    fid = np.lib._datasource.open(fname, 'rt', encoding=encoding)
  File "/home/katebrich/anaconda3/lib/python3.7/site-packages/numpy/lib/_datasource.py", line 269, in open
    return ds.open(path, mode, encoding=encoding, newline=newline)
  File "/home/katebrich/anaconda3/lib/python3.7/site-packages/numpy/lib/_datasource.py", line 623, in open
    raise IOError("%s not found." % path)
OSError: /home/katebrich/Documents/diplomka/datasets/pipeline_test/lbs/XXXXX.txt not found.
2020-08-19 17:49:29,585 [ERROR] run_analysis.py(line 54) 2/8: XXXX X NOT PROCESSED !
2020-08-19 17:49:29,587 [ERROR] run_analysis.py(line 48) Error while processing 148l E: /home/katebrich/Documents/diplomka/datasets/pipeline_test/features/pdbkb_conservation/148lE.txt not found.
Traceback (most recent call last):
  File "./pythonScripts/run_analysis.py", line 29, in compute_pairs
    feature = np.genfromtxt(file, delimiter=' ')
  File "/home/katebrich/anaconda3/lib/python3.7/site-packages/numpy/lib/npyio.py", line 1772, in genfromtxt
    fid = np.lib._datasource.open(fname, 'rt', encoding=encoding)
  File "/home/katebrich/anaconda3/lib/python3.7/site-packages/numpy/lib/_datasource.py", line 269, in open
    return ds.open(path, mode, encoding=encoding, newline=newline)
  File "/home/katebrich/anaconda3/lib/python3.7/site-packages/numpy/lib/_datasource.py", line 623, in open
    raise IOError("%s not found." % path)
OSError: /home/katebrich/Documents/diplomka/datasets/pipeline_test/features/pdbkb_conservation/148lE.txt not found.
2020-08-19 17:49:29,587 [ERROR] run_analysis.py(line 54) 4/8: 148l E NOT PROCESSED !
2020-08-19 17:49:29,590 [ERROR] run_analysis.py(line 48) Error while processing 1igy B: /home/katebrich/Documents/diplomka/datasets/pipeline_test/features/pdbkb_conservation/1igyB.txt not found.
Traceback (most recent call last):
  File "./pythonScripts/run_analysis.py", line 29, in compute_pairs
    feature = np.genfromtxt(file, delimiter=' ')
  File "/home/katebrich/anaconda3/lib/python3.7/site-packages/numpy/lib/npyio.py", line 1772, in genfromtxt
    fid = np.lib._datasource.open(fname, 'rt', encoding=encoding)
  File "/home/katebrich/anaconda3/lib/python3.7/site-packages/numpy/lib/_datasource.py", line 269, in open
    return ds.open(path, mode, encoding=encoding, newline=newline)
  File "/home/katebrich/anaconda3/lib/python3.7/site-packages/numpy/lib/_datasource.py", line 623, in open
    raise IOError("%s not found." % path)
OSError: /home/katebrich/Documents/diplomka/datasets/pipeline_test/features/pdbkb_conservation/1igyB.txt not found.
2020-08-19 17:49:29,590 [ERROR] run_analysis.py(line 54) 5/8: 1igy B NOT PROCESSED !
2020-08-19 17:49:29,592 [ERROR] run_analysis.py(line 48) Error while processing 1exa A: /home/katebrich/Documents/diplomka/datasets/pipeline_test/features/pdbkb_conservation/1exaA.txt not found.
Traceback (most recent call last):
  File "./pythonScripts/run_analysis.py", line 29, in compute_pairs
    feature = np.genfromtxt(file, delimiter=' ')
  File "/home/katebrich/anaconda3/lib/python3.7/site-packages/numpy/lib/npyio.py", line 1772, in genfromtxt
    fid = np.lib._datasource.open(fname, 'rt', encoding=encoding)
  File "/home/katebrich/anaconda3/lib/python3.7/site-packages/numpy/lib/_datasource.py", line 269, in open
    return ds.open(path, mode, encoding=encoding, newline=newline)
  File "/home/katebrich/anaconda3/lib/python3.7/site-packages/numpy/lib/_datasource.py", line 623, in open
    raise IOError("%s not found." % path)
OSError: /home/katebrich/Documents/diplomka/datasets/pipeline_test/features/pdbkb_conservation/1exaA.txt not found.
2020-08-19 17:49:29,592 [ERROR] run_analysis.py(line 54) 6/8: 1exa A NOT PROCESSED !
2020-08-19 17:49:29,597 [ERROR] run_analysis.py(line 48) Error while processing 3ldk A: /home/katebrich/Documents/diplomka/datasets/pipeline_test/features/pdbkb_conservation/3ldkA.txt not found.
Traceback (most recent call last):
  File "./pythonScripts/run_analysis.py", line 29, in compute_pairs
    feature = np.genfromtxt(file, delimiter=' ')
  File "/home/katebrich/anaconda3/lib/python3.7/site-packages/numpy/lib/npyio.py", line 1772, in genfromtxt
    fid = np.lib._datasource.open(fname, 'rt', encoding=encoding)
  File "/home/katebrich/anaconda3/lib/python3.7/site-packages/numpy/lib/_datasource.py", line 269, in open
    return ds.open(path, mode, encoding=encoding, newline=newline)
  File "/home/katebrich/anaconda3/lib/python3.7/site-packages/numpy/lib/_datasource.py", line 623, in open
    raise IOError("%s not found." % path)
OSError: /home/katebrich/Documents/diplomka/datasets/pipeline_test/features/pdbkb_conservation/3ldkA.txt not found.
2020-08-19 17:49:29,597 [ERROR] run_analysis.py(line 54) 8/8: 3ldk A NOT PROCESSED !
2020-08-19 17:49:29,599 [ERROR] run_analysis.py(line 48) Error while processing 2amb A: /home/katebrich/Documents/diplomka/datasets/pipeline_test/features/pdbkb_conservation/2ambA.txt not found.
Traceback (most recent call last):
  File "./pythonScripts/run_analysis.py", line 29, in compute_pairs
    feature = np.genfromtxt(file, delimiter=' ')
  File "/home/katebrich/anaconda3/lib/python3.7/site-packages/numpy/lib/npyio.py", line 1772, in genfromtxt
    fid = np.lib._datasource.open(fname, 'rt', encoding=encoding)
  File "/home/katebrich/anaconda3/lib/python3.7/site-packages/numpy/lib/_datasource.py", line 269, in open
    return ds.open(path, mode, encoding=encoding, newline=newline)
  File "/home/katebrich/anaconda3/lib/python3.7/site-packages/numpy/lib/_datasource.py", line 623, in open
    raise IOError("%s not found." % path)
OSError: /home/katebrich/Documents/diplomka/datasets/pipeline_test/features/pdbkb_conservation/2ambA.txt not found.
2020-08-19 17:49:29,599 [ERROR] run_analysis.py(line 54) 9/8: 2amb A NOT PROCESSED !
2020-08-19 17:49:29,599 [WARNING] run_analysis.py(line 121) Some structures were not processed successfully: skipping them in the analysis...
 XXXX X
148l E
1igy B
1exa A
3ldk A
2amb A
2020-08-19 17:58:36,797 [INFO] download_dataset.py(line 145) Downloading structures from /home/katebrich/Documents/diplomka/datasets/test.txt to /home/katebrich/Documents/diplomka/datasets/pipeline_test started...
2020-08-19 17:58:37,162 [ERROR] download_dataset.py(line 91) Error while downloading XXXX X: HTTP Error 404: Not Found
Traceback (most recent call last):
  File "./pythonScripts/download_dataset.py", line 83, in download_structure
    get_PDB(temp_file, output_PDB, pdb_id, chain_ids, ligands_filter)
  File "./pythonScripts/download_dataset.py", line 33, in get_PDB
    response = restAPI_get(url)
  File "/home/katebrich/Documents/diplomka/GitHub/pythonScripts/helper.py", line 41, in restAPI_get
    with urllib.request.urlopen(req) as f:
  File "/home/katebrich/anaconda3/lib/python3.7/urllib/request.py", line 222, in urlopen
    return opener.open(url, data, timeout)
  File "/home/katebrich/anaconda3/lib/python3.7/urllib/request.py", line 531, in open
    response = meth(req, response)
  File "/home/katebrich/anaconda3/lib/python3.7/urllib/request.py", line 641, in http_response
    'http', request, response, code, msg, hdrs)
  File "/home/katebrich/anaconda3/lib/python3.7/urllib/request.py", line 569, in error
    return self._call_chain(*args)
  File "/home/katebrich/anaconda3/lib/python3.7/urllib/request.py", line 503, in _call_chain
    result = func(*args)
  File "/home/katebrich/anaconda3/lib/python3.7/urllib/request.py", line 649, in http_error_default
    raise HTTPError(req.full_url, code, msg, hdrs, fp)
urllib.error.HTTPError: HTTP Error 404: Not Found
2020-08-19 17:58:37,167 [ERROR] download_dataset.py(line 101) 1/8: XXXX X NOT DOWNLOADED !
2020-08-19 17:58:59,745 [WARNING] download_dataset.py(line 166) Downloading structures finished: Some structures were not downloaded successfully: 
 XXXX X
2020-08-19 17:58:59,925 [INFO] create_mappings_cache.py(line 69) Creating mapping cache started...
2020-08-19 17:59:00,246 [ERROR] create_mappings_cache.py(line 25) Error while processing XXXX X: HTTP Error 404: Not Found
Traceback (most recent call last):
  File "./pythonScripts/create_mappings_cache.py", line 17, in create_mappings_cache
    mappings = res_mappings_author_to_pdbe(pdb_id, chain_id)
  File "/home/katebrich/Documents/diplomka/GitHub/pythonScripts/helper.py", line 112, in res_mappings_author_to_pdbe
    response = restAPI_get_json(f"https://www.ebi.ac.uk/pdbe/api/pdb/entry/residue_listing/{pdb_id}/chain/{chain_id}")
  File "/home/katebrich/Documents/diplomka/GitHub/pythonScripts/helper.py", line 47, in restAPI_get_json
    return json.loads(restAPI_get(url))
  File "/home/katebrich/Documents/diplomka/GitHub/pythonScripts/helper.py", line 41, in restAPI_get
    with urllib.request.urlopen(req) as f:
  File "/home/katebrich/anaconda3/lib/python3.7/urllib/request.py", line 222, in urlopen
    return opener.open(url, data, timeout)
  File "/home/katebrich/anaconda3/lib/python3.7/urllib/request.py", line 531, in open
    response = meth(req, response)
  File "/home/katebrich/anaconda3/lib/python3.7/urllib/request.py", line 641, in http_response
    'http', request, response, code, msg, hdrs)
  File "/home/katebrich/anaconda3/lib/python3.7/urllib/request.py", line 569, in error
    return self._call_chain(*args)
  File "/home/katebrich/anaconda3/lib/python3.7/urllib/request.py", line 503, in _call_chain
    result = func(*args)
  File "/home/katebrich/anaconda3/lib/python3.7/urllib/request.py", line 649, in http_error_default
    raise HTTPError(req.full_url, code, msg, hdrs, fp)
urllib.error.HTTPError: HTTP Error 404: Not Found
2020-08-19 17:59:00,251 [ERROR] create_mappings_cache.py(line 33) 1/8: XXXX X NOT PROCESSED !
2020-08-19 17:59:02,913 [WARNING] create_mappings_cache.py(line 89) Creating mapping cache finished: Some structures were not processed successfully: 
 XXXX X
2020-08-19 17:59:03,173 [INFO] compute_ligand_binding_sites.py(line 118) Computing ligand binding sites started...
2020-08-19 17:59:03,177 [ERROR] compute_ligand_binding_sites.py(line 26) Error while processing XXXX X: [Errno 2] No such file or directory: '/home/katebrich/Documents/diplomka/datasets/pipeline_test/PDB/XXXXX.pdb'
Traceback (most recent call last):
  File "./pythonScripts/compute_ligand_binding_sites.py", line 18, in __get_ligand_binding_site
    lbs = __compute_ligand_binding_sites(pdb_id, chain_id, pdb_path)
  File "./pythonScripts/compute_ligand_binding_sites.py", line 44, in __compute_ligand_binding_sites
    structure = parser.get_structure(pdb_id + chain_id, pdb_file_path)
  File "/home/katebrich/anaconda3/lib/python3.7/site-packages/Bio/PDB/PDBParser.py", line 88, in get_structure
    with as_handle(file, mode="rU") as handle:
  File "/home/katebrich/anaconda3/lib/python3.7/contextlib.py", line 112, in __enter__
    return next(self.gen)
  File "/home/katebrich/anaconda3/lib/python3.7/site-packages/Bio/File.py", line 120, in as_handle
    with open(handleish, mode, **kwargs) as fp:
FileNotFoundError: [Errno 2] No such file or directory: '/home/katebrich/Documents/diplomka/datasets/pipeline_test/PDB/XXXXX.pdb'
2020-08-19 17:59:03,215 [ERROR] compute_ligand_binding_sites.py(line 34) 1/8: XXXX X NOT PROCESSED !
2020-08-19 17:59:07,866 [WARNING] compute_ligand_binding_sites.py(line 138) Computing ligand binding sites finished: Some structures were not processed successfully: 
 XXXX X
2020-08-19 17:59:09,267 [INFO] compute_feature.py(line 81) Computing feature pdbkb_conservation started...
2020-08-19 17:59:09,578 [ERROR] compute_feature.py(line 28) Error while processing XXXX X: HTTP Error 404: Not Found
Traceback (most recent call last):
  File "./pythonScripts/compute_feature.py", line 19, in __compute_feature
    feat_vals = get_feature(name_of_feature, input_dir, pdb_id, chain_id)
  File "/home/katebrich/Documents/diplomka/GitHub/pythonScripts/features.py", line 15, in get_feature
    return get_pdbkb_conservation(data_dir, pdb_id, chain_id)
  File "/home/katebrich/Documents/diplomka/GitHub/pythonScripts/features.py", line 190, in get_pdbkb_conservation
    entities = get_uniprot_entity(pdb_id, chain_id)
  File "/home/katebrich/Documents/diplomka/GitHub/pythonScripts/helper.py", line 12, in get_uniprot_entity
    parsedResponse = restAPI_get_json(url)
  File "/home/katebrich/Documents/diplomka/GitHub/pythonScripts/helper.py", line 47, in restAPI_get_json
    return json.loads(restAPI_get(url))
  File "/home/katebrich/Documents/diplomka/GitHub/pythonScripts/helper.py", line 41, in restAPI_get
    with urllib.request.urlopen(req) as f:
  File "/home/katebrich/anaconda3/lib/python3.7/urllib/request.py", line 222, in urlopen
    return opener.open(url, data, timeout)
  File "/home/katebrich/anaconda3/lib/python3.7/urllib/request.py", line 531, in open
    response = meth(req, response)
  File "/home/katebrich/anaconda3/lib/python3.7/urllib/request.py", line 641, in http_response
    'http', request, response, code, msg, hdrs)
  File "/home/katebrich/anaconda3/lib/python3.7/urllib/request.py", line 569, in error
    return self._call_chain(*args)
  File "/home/katebrich/anaconda3/lib/python3.7/urllib/request.py", line 503, in _call_chain
    result = func(*args)
  File "/home/katebrich/anaconda3/lib/python3.7/urllib/request.py", line 649, in http_error_default
    raise HTTPError(req.full_url, code, msg, hdrs, fp)
urllib.error.HTTPError: HTTP Error 404: Not Found
2020-08-19 17:59:09,582 [ERROR] compute_feature.py(line 36) 1/8: XXXX X NOT PROCESSED !
2020-08-19 17:59:10,320 [ERROR] compute_feature.py(line 28) Error while processing 2g46 A: 'int' object is not subscriptable
Traceback (most recent call last):
  File "./pythonScripts/compute_feature.py", line 23, in __compute_feature
    f.write('\n'.join('{} {}'.format(x[0], x[1]) for x in feat_vals))
  File "./pythonScripts/compute_feature.py", line 23, in <genexpr>
    f.write('\n'.join('{} {}'.format(x[0], x[1]) for x in feat_vals))
TypeError: 'int' object is not subscriptable
2020-08-19 17:59:10,320 [ERROR] compute_feature.py(line 36) 2/8: 2g46 A NOT PROCESSED !
2020-08-19 17:59:10,420 [ERROR] compute_feature.py(line 28) Error while processing 148l E: 'int' object is not subscriptable
Traceback (most recent call last):
  File "./pythonScripts/compute_feature.py", line 23, in __compute_feature
    f.write('\n'.join('{} {}'.format(x[0], x[1]) for x in feat_vals))
  File "./pythonScripts/compute_feature.py", line 23, in <genexpr>
    f.write('\n'.join('{} {}'.format(x[0], x[1]) for x in feat_vals))
TypeError: 'int' object is not subscriptable
2020-08-19 17:59:10,420 [ERROR] compute_feature.py(line 36) 3/8: 148l E NOT PROCESSED !
2020-08-19 17:59:10,867 [ERROR] compute_feature.py(line 28) Error while processing 1exa A: 'int' object is not subscriptable
Traceback (most recent call last):
  File "./pythonScripts/compute_feature.py", line 23, in __compute_feature
    f.write('\n'.join('{} {}'.format(x[0], x[1]) for x in feat_vals))
  File "./pythonScripts/compute_feature.py", line 23, in <genexpr>
    f.write('\n'.join('{} {}'.format(x[0], x[1]) for x in feat_vals))
TypeError: 'int' object is not subscriptable
2020-08-19 17:59:10,867 [ERROR] compute_feature.py(line 36) 4/8: 1exa A NOT PROCESSED !
2020-08-19 17:59:11,026 [ERROR] compute_feature.py(line 28) Error while processing 1igy B: list assignment index out of range
Traceback (most recent call last):
  File "./pythonScripts/compute_feature.py", line 19, in __compute_feature
    feat_vals = get_feature(name_of_feature, input_dir, pdb_id, chain_id)
  File "/home/katebrich/Documents/diplomka/GitHub/pythonScripts/features.py", line 15, in get_feature
    return get_pdbkb_conservation(data_dir, pdb_id, chain_id)
  File "/home/katebrich/Documents/diplomka/GitHub/pythonScripts/features.py", line 214, in get_pdbkb_conservation
    feature_vector[feat_begin-1] = resi["conservation_score"]
IndexError: list assignment index out of range
2020-08-19 17:59:11,028 [ERROR] compute_feature.py(line 36) 5/8: 1igy B NOT PROCESSED !
2020-08-19 17:59:12,315 [ERROR] compute_feature.py(line 28) Error while processing 2amb A: 'int' object is not subscriptable
Traceback (most recent call last):
  File "./pythonScripts/compute_feature.py", line 23, in __compute_feature
    f.write('\n'.join('{} {}'.format(x[0], x[1]) for x in feat_vals))
  File "./pythonScripts/compute_feature.py", line 23, in <genexpr>
    f.write('\n'.join('{} {}'.format(x[0], x[1]) for x in feat_vals))
TypeError: 'int' object is not subscriptable
2020-08-19 17:59:12,315 [ERROR] compute_feature.py(line 36) 6/8: 2amb A NOT PROCESSED !
2020-08-19 17:59:12,556 [ERROR] compute_feature.py(line 28) Error while processing 3ldk A: list assignment index out of range
Traceback (most recent call last):
  File "./pythonScripts/compute_feature.py", line 19, in __compute_feature
    feat_vals = get_feature(name_of_feature, input_dir, pdb_id, chain_id)
  File "/home/katebrich/Documents/diplomka/GitHub/pythonScripts/features.py", line 15, in get_feature
    return get_pdbkb_conservation(data_dir, pdb_id, chain_id)
  File "/home/katebrich/Documents/diplomka/GitHub/pythonScripts/features.py", line 214, in get_pdbkb_conservation
    feature_vector[feat_begin-1] = resi["conservation_score"]
IndexError: list assignment index out of range
2020-08-19 17:59:12,559 [ERROR] compute_feature.py(line 36) 7/8: 3ldk A NOT PROCESSED !
2020-08-19 17:59:13,477 [ERROR] compute_feature.py(line 28) Error while processing 1qhi A: 'int' object is not subscriptable
Traceback (most recent call last):
  File "./pythonScripts/compute_feature.py", line 23, in __compute_feature
    f.write('\n'.join('{} {}'.format(x[0], x[1]) for x in feat_vals))
  File "./pythonScripts/compute_feature.py", line 23, in <genexpr>
    f.write('\n'.join('{} {}'.format(x[0], x[1]) for x in feat_vals))
TypeError: 'int' object is not subscriptable
2020-08-19 17:59:13,478 [ERROR] compute_feature.py(line 36) 8/8: 1qhi A NOT PROCESSED !
2020-08-19 17:59:13,478 [WARNING] compute_feature.py(line 102) Computing feature pdbkb_conservation finished: Some structures were not processed successfully: 
 XXXX X
2g46 A
148l E
1exa A
1igy B
2amb A
3ldk A
1qhi A
2020-08-19 17:59:15,882 [INFO] run_analysis.py(line 107) Running analysis started...
2020-08-19 17:59:15,882 [ERROR] run_analysis.py(line 48) Error while processing XXXX X: /home/katebrich/Documents/diplomka/datasets/pipeline_test/lbs/XXXXX.txt not found.
Traceback (most recent call last):
  File "./pythonScripts/run_analysis.py", line 24, in compute_pairs
    lbs = np.genfromtxt(file, delimiter=' ')
  File "/home/katebrich/anaconda3/lib/python3.7/site-packages/numpy/lib/npyio.py", line 1772, in genfromtxt
    fid = np.lib._datasource.open(fname, 'rt', encoding=encoding)
  File "/home/katebrich/anaconda3/lib/python3.7/site-packages/numpy/lib/_datasource.py", line 269, in open
    return ds.open(path, mode, encoding=encoding, newline=newline)
  File "/home/katebrich/anaconda3/lib/python3.7/site-packages/numpy/lib/_datasource.py", line 623, in open
    raise IOError("%s not found." % path)
OSError: /home/katebrich/Documents/diplomka/datasets/pipeline_test/lbs/XXXXX.txt not found.
2020-08-19 17:59:15,883 [ERROR] run_analysis.py(line 54) 2/8: XXXX X NOT PROCESSED !
2020-08-19 17:59:15,888 [ERROR] run_analysis.py(line 48) Error while processing 1igy B: /home/katebrich/Documents/diplomka/datasets/pipeline_test/features/pdbkb_conservation/1igyB.txt not found.
Traceback (most recent call last):
  File "./pythonScripts/run_analysis.py", line 29, in compute_pairs
    feature = np.genfromtxt(file, delimiter=' ')
  File "/home/katebrich/anaconda3/lib/python3.7/site-packages/numpy/lib/npyio.py", line 1772, in genfromtxt
    fid = np.lib._datasource.open(fname, 'rt', encoding=encoding)
  File "/home/katebrich/anaconda3/lib/python3.7/site-packages/numpy/lib/_datasource.py", line 269, in open
    return ds.open(path, mode, encoding=encoding, newline=newline)
  File "/home/katebrich/anaconda3/lib/python3.7/site-packages/numpy/lib/_datasource.py", line 623, in open
    raise IOError("%s not found." % path)
OSError: /home/katebrich/Documents/diplomka/datasets/pipeline_test/features/pdbkb_conservation/1igyB.txt not found.
2020-08-19 17:59:15,888 [ERROR] run_analysis.py(line 54) 5/8: 1igy B NOT PROCESSED !
2020-08-19 17:59:15,894 [ERROR] run_analysis.py(line 48) Error while processing 3ldk A: /home/katebrich/Documents/diplomka/datasets/pipeline_test/features/pdbkb_conservation/3ldkA.txt not found.
Traceback (most recent call last):
  File "./pythonScripts/run_analysis.py", line 29, in compute_pairs
    feature = np.genfromtxt(file, delimiter=' ')
  File "/home/katebrich/anaconda3/lib/python3.7/site-packages/numpy/lib/npyio.py", line 1772, in genfromtxt
    fid = np.lib._datasource.open(fname, 'rt', encoding=encoding)
  File "/home/katebrich/anaconda3/lib/python3.7/site-packages/numpy/lib/_datasource.py", line 269, in open
    return ds.open(path, mode, encoding=encoding, newline=newline)
  File "/home/katebrich/anaconda3/lib/python3.7/site-packages/numpy/lib/_datasource.py", line 623, in open
    raise IOError("%s not found." % path)
OSError: /home/katebrich/Documents/diplomka/datasets/pipeline_test/features/pdbkb_conservation/3ldkA.txt not found.
2020-08-19 17:59:15,895 [ERROR] run_analysis.py(line 54) 8/8: 3ldk A NOT PROCESSED !
2020-08-19 17:59:15,896 [WARNING] run_analysis.py(line 121) Some structures were not processed successfully: skipping them in the analysis...
 XXXX X
1igy B
3ldk A
2020-08-19 18:03:11,672 [INFO] compute_feature.py(line 81) Computing feature pdbkb_conservation started...
2020-08-19 18:03:12,021 [ERROR] compute_feature.py(line 28) Error while processing XXXX X: HTTP Error 404: Not Found
Traceback (most recent call last):
  File "./pythonScripts/compute_feature.py", line 19, in __compute_feature
    feat_vals = get_feature(name_of_feature, input_dir, pdb_id, chain_id)
  File "/home/katebrich/Documents/diplomka/GitHub/pythonScripts/features.py", line 15, in get_feature
    return get_pdbkb_conservation(data_dir, pdb_id, chain_id)
  File "/home/katebrich/Documents/diplomka/GitHub/pythonScripts/features.py", line 190, in get_pdbkb_conservation
    entities = get_uniprot_entity(pdb_id, chain_id)
  File "/home/katebrich/Documents/diplomka/GitHub/pythonScripts/helper.py", line 12, in get_uniprot_entity
    parsedResponse = restAPI_get_json(url)
  File "/home/katebrich/Documents/diplomka/GitHub/pythonScripts/helper.py", line 47, in restAPI_get_json
    return json.loads(restAPI_get(url))
  File "/home/katebrich/Documents/diplomka/GitHub/pythonScripts/helper.py", line 41, in restAPI_get
    with urllib.request.urlopen(req) as f:
  File "/home/katebrich/anaconda3/lib/python3.7/urllib/request.py", line 222, in urlopen
    return opener.open(url, data, timeout)
  File "/home/katebrich/anaconda3/lib/python3.7/urllib/request.py", line 531, in open
    response = meth(req, response)
  File "/home/katebrich/anaconda3/lib/python3.7/urllib/request.py", line 641, in http_response
    'http', request, response, code, msg, hdrs)
  File "/home/katebrich/anaconda3/lib/python3.7/urllib/request.py", line 569, in error
    return self._call_chain(*args)
  File "/home/katebrich/anaconda3/lib/python3.7/urllib/request.py", line 503, in _call_chain
    result = func(*args)
  File "/home/katebrich/anaconda3/lib/python3.7/urllib/request.py", line 649, in http_error_default
    raise HTTPError(req.full_url, code, msg, hdrs, fp)
urllib.error.HTTPError: HTTP Error 404: Not Found
2020-08-19 18:03:12,064 [ERROR] compute_feature.py(line 36) 1/8: XXXX X NOT PROCESSED !
2020-08-19 18:03:12,828 [ERROR] compute_feature.py(line 28) Error while processing 2g46 A: 'int' object is not subscriptable
Traceback (most recent call last):
  File "./pythonScripts/compute_feature.py", line 23, in __compute_feature
    f.write('\n'.join('{} {}'.format(x[0], x[1]) for x in feat_vals))
  File "./pythonScripts/compute_feature.py", line 23, in <genexpr>
    f.write('\n'.join('{} {}'.format(x[0], x[1]) for x in feat_vals))
TypeError: 'int' object is not subscriptable
2020-08-19 18:03:12,828 [ERROR] compute_feature.py(line 36) 2/8: 2g46 A NOT PROCESSED !
2020-08-19 18:03:13,083 [ERROR] compute_feature.py(line 28) Error while processing 148l E: 'int' object is not subscriptable
Traceback (most recent call last):
  File "./pythonScripts/compute_feature.py", line 23, in __compute_feature
    f.write('\n'.join('{} {}'.format(x[0], x[1]) for x in feat_vals))
  File "./pythonScripts/compute_feature.py", line 23, in <genexpr>
    f.write('\n'.join('{} {}'.format(x[0], x[1]) for x in feat_vals))
TypeError: 'int' object is not subscriptable
2020-08-19 18:03:13,083 [ERROR] compute_feature.py(line 36) 3/8: 148l E NOT PROCESSED !
2020-08-19 18:03:13,256 [ERROR] compute_feature.py(line 28) Error while processing 1igy B: list assignment index out of range
Traceback (most recent call last):
  File "./pythonScripts/compute_feature.py", line 19, in __compute_feature
    feat_vals = get_feature(name_of_feature, input_dir, pdb_id, chain_id)
  File "/home/katebrich/Documents/diplomka/GitHub/pythonScripts/features.py", line 15, in get_feature
    return get_pdbkb_conservation(data_dir, pdb_id, chain_id)
  File "/home/katebrich/Documents/diplomka/GitHub/pythonScripts/features.py", line 214, in get_pdbkb_conservation
    feature_vector[feat_begin-1] = resi["conservation_score"]
IndexError: list assignment index out of range
2020-08-19 18:03:13,258 [ERROR] compute_feature.py(line 36) 4/8: 1igy B NOT PROCESSED !
2020-08-19 18:03:13,504 [ERROR] compute_feature.py(line 28) Error while processing 1exa A: 'int' object is not subscriptable
Traceback (most recent call last):
  File "./pythonScripts/compute_feature.py", line 23, in __compute_feature
    f.write('\n'.join('{} {}'.format(x[0], x[1]) for x in feat_vals))
  File "./pythonScripts/compute_feature.py", line 23, in <genexpr>
    f.write('\n'.join('{} {}'.format(x[0], x[1]) for x in feat_vals))
TypeError: 'int' object is not subscriptable
2020-08-19 18:03:13,504 [ERROR] compute_feature.py(line 36) 5/8: 1exa A NOT PROCESSED !
2020-08-19 18:03:14,374 [ERROR] compute_feature.py(line 28) Error while processing 1qhi A: 'int' object is not subscriptable
Traceback (most recent call last):
  File "./pythonScripts/compute_feature.py", line 23, in __compute_feature
    f.write('\n'.join('{} {}'.format(x[0], x[1]) for x in feat_vals))
  File "./pythonScripts/compute_feature.py", line 23, in <genexpr>
    f.write('\n'.join('{} {}'.format(x[0], x[1]) for x in feat_vals))
TypeError: 'int' object is not subscriptable
2020-08-19 18:03:14,375 [ERROR] compute_feature.py(line 36) 6/8: 1qhi A NOT PROCESSED !
2020-08-19 18:03:14,884 [ERROR] compute_feature.py(line 28) Error while processing 3ldk A: list assignment index out of range
Traceback (most recent call last):
  File "./pythonScripts/compute_feature.py", line 19, in __compute_feature
    feat_vals = get_feature(name_of_feature, input_dir, pdb_id, chain_id)
  File "/home/katebrich/Documents/diplomka/GitHub/pythonScripts/features.py", line 15, in get_feature
    return get_pdbkb_conservation(data_dir, pdb_id, chain_id)
  File "/home/katebrich/Documents/diplomka/GitHub/pythonScripts/features.py", line 214, in get_pdbkb_conservation
    feature_vector[feat_begin-1] = resi["conservation_score"]
IndexError: list assignment index out of range
2020-08-19 18:03:14,887 [ERROR] compute_feature.py(line 36) 7/8: 3ldk A NOT PROCESSED !
2020-08-19 18:03:15,596 [ERROR] compute_feature.py(line 28) Error while processing 2amb A: 'int' object is not subscriptable
Traceback (most recent call last):
  File "./pythonScripts/compute_feature.py", line 23, in __compute_feature
    f.write('\n'.join('{} {}'.format(x[0], x[1]) for x in feat_vals))
  File "./pythonScripts/compute_feature.py", line 23, in <genexpr>
    f.write('\n'.join('{} {}'.format(x[0], x[1]) for x in feat_vals))
TypeError: 'int' object is not subscriptable
2020-08-19 18:03:15,596 [ERROR] compute_feature.py(line 36) 8/8: 2amb A NOT PROCESSED !
2020-08-19 18:03:15,596 [WARNING] compute_feature.py(line 102) Computing feature pdbkb_conservation finished: Some structures were not processed successfully: 
 XXXX X
2g46 A
148l E
1igy B
1exa A
1qhi A
3ldk A
2amb A
2020-08-19 18:05:04,587 [INFO] compute_feature.py(line 81) Computing feature pdbkb_conservation started...
2020-08-19 18:05:04,911 [ERROR] compute_feature.py(line 28) Error while processing XXXX X: HTTP Error 404: Not Found
Traceback (most recent call last):
  File "./pythonScripts/compute_feature.py", line 19, in __compute_feature
    feat_vals = get_feature(name_of_feature, input_dir, pdb_id, chain_id)
  File "/home/katebrich/Documents/diplomka/GitHub/pythonScripts/features.py", line 15, in get_feature
    return get_pdbkb_conservation(data_dir, pdb_id, chain_id)
  File "/home/katebrich/Documents/diplomka/GitHub/pythonScripts/features.py", line 190, in get_pdbkb_conservation
    entities = get_uniprot_entity(pdb_id, chain_id)
  File "/home/katebrich/Documents/diplomka/GitHub/pythonScripts/helper.py", line 12, in get_uniprot_entity
    parsedResponse = restAPI_get_json(url)
  File "/home/katebrich/Documents/diplomka/GitHub/pythonScripts/helper.py", line 47, in restAPI_get_json
    return json.loads(restAPI_get(url))
  File "/home/katebrich/Documents/diplomka/GitHub/pythonScripts/helper.py", line 41, in restAPI_get
    with urllib.request.urlopen(req) as f:
  File "/home/katebrich/anaconda3/lib/python3.7/urllib/request.py", line 222, in urlopen
    return opener.open(url, data, timeout)
  File "/home/katebrich/anaconda3/lib/python3.7/urllib/request.py", line 531, in open
    response = meth(req, response)
  File "/home/katebrich/anaconda3/lib/python3.7/urllib/request.py", line 641, in http_response
    'http', request, response, code, msg, hdrs)
  File "/home/katebrich/anaconda3/lib/python3.7/urllib/request.py", line 569, in error
    return self._call_chain(*args)
  File "/home/katebrich/anaconda3/lib/python3.7/urllib/request.py", line 503, in _call_chain
    result = func(*args)
  File "/home/katebrich/anaconda3/lib/python3.7/urllib/request.py", line 649, in http_error_default
    raise HTTPError(req.full_url, code, msg, hdrs, fp)
urllib.error.HTTPError: HTTP Error 404: Not Found
2020-08-19 18:05:04,979 [ERROR] compute_feature.py(line 36) 1/8: XXXX X NOT PROCESSED !
2020-08-19 18:05:26,499 [WARNING] compute_feature.py(line 102) Computing feature pdbkb_conservation finished: Some structures were not processed successfully: 
 XXXX X
2020-08-19 18:07:14,710 [INFO] compute_feature.py(line 81) Computing feature pdbkb_conservation started...
2020-08-19 18:10:04,107 [INFO] compute_feature.py(line 99) Computing feature pdbkb_conservation finished: All structures processed successfully.
2020-08-19 18:10:06,099 [INFO] run_analysis.py(line 107) Running analysis started...
2020-08-19 18:10:07,188 [INFO] run_analysis.py(line 118) All structures processed successfully.
2020-08-21 09:25:28,825 [INFO] run_analysis.py(line 107) Running analysis started...
2020-08-21 09:25:29,598 [INFO] run_analysis.py(line 118) All structures processed successfully.
2020-08-21 09:25:29,667 [INFO] run_analysis.py(line 137) Running analysis finished. Results saved to /home/katebrich/Documents/diplomka/datasets/TEST_pipeline/analysis/pdbkb_conservation/results.txt
2020-08-21 10:36:05,266 [INFO] run_analysis.py(line 107) Running analysis started...
2020-08-21 10:36:06,017 [INFO] run_analysis.py(line 118) All structures processed successfully.
2020-08-21 10:36:25,799 [INFO] run_analysis.py(line 107) Running analysis started...
2020-08-21 10:36:26,540 [INFO] run_analysis.py(line 118) All structures processed successfully.
2020-08-21 10:36:50,822 [INFO] run_analysis.py(line 107) Running analysis started...
2020-08-21 10:36:51,592 [INFO] run_analysis.py(line 118) All structures processed successfully.
2020-08-21 10:36:51,593 [INFO] run_analysis.py(line 133) Running Welch's T-test
2020-08-21 10:36:51,663 [INFO] run_analysis.py(line 142) Running analysis finished. Results saved to /home/katebrich/Documents/diplomka/datasets/TEST_pipeline/analysis/pdbkb_conservation/results.txt
2020-08-21 15:18:43,584 [INFO] compute_feature.py(line 81) Computing feature pdbkb_conservation started...
2020-08-21 15:19:42,762 [ERROR] compute_feature.py(line 28) Error while processing 1rqj A: HTTP Error 500: Internal Server Error
Traceback (most recent call last):
  File "./pythonScripts/compute_feature.py", line 19, in __compute_feature
    feat_vals = get_feature(name_of_feature, input_dir, pdb_id, chain_id)
  File "/home/katebrich/Documents/diplomka/GitHub/pythonScripts/features.py", line 15, in get_feature
    return get_pdbkb_conservation(data_dir, pdb_id, chain_id)
  File "/home/katebrich/Documents/diplomka/GitHub/pythonScripts/features.py", line 200, in get_pdbkb_conservation
    response = restAPI_get_json(url)
  File "/home/katebrich/Documents/diplomka/GitHub/pythonScripts/helper.py", line 47, in restAPI_get_json
    return json.loads(restAPI_get(url))
  File "/home/katebrich/Documents/diplomka/GitHub/pythonScripts/helper.py", line 41, in restAPI_get
    with urllib.request.urlopen(req) as f:
  File "/home/katebrich/anaconda3/lib/python3.7/urllib/request.py", line 222, in urlopen
    return opener.open(url, data, timeout)
  File "/home/katebrich/anaconda3/lib/python3.7/urllib/request.py", line 531, in open
    response = meth(req, response)
  File "/home/katebrich/anaconda3/lib/python3.7/urllib/request.py", line 641, in http_response
    'http', request, response, code, msg, hdrs)
  File "/home/katebrich/anaconda3/lib/python3.7/urllib/request.py", line 569, in error
    return self._call_chain(*args)
  File "/home/katebrich/anaconda3/lib/python3.7/urllib/request.py", line 503, in _call_chain
    result = func(*args)
  File "/home/katebrich/anaconda3/lib/python3.7/urllib/request.py", line 649, in http_error_default
    raise HTTPError(req.full_url, code, msg, hdrs, fp)
urllib.error.HTTPError: HTTP Error 500: Internal Server Error
2020-08-21 15:19:42,767 [ERROR] compute_feature.py(line 36) 46/250: 1rqj A NOT PROCESSED !
2020-08-21 15:22:41,662 [ERROR] compute_feature.py(line 28) Error while processing 1lii A: <urlopen error TLS/SSL connection has been closed (EOF) (_ssl.c:1076)>
Traceback (most recent call last):
  File "/home/katebrich/anaconda3/lib/python3.7/urllib/request.py", line 1319, in do_open
    encode_chunked=req.has_header('Transfer-encoding'))
  File "/home/katebrich/anaconda3/lib/python3.7/http/client.py", line 1252, in request
    self._send_request(method, url, body, headers, encode_chunked)
  File "/home/katebrich/anaconda3/lib/python3.7/http/client.py", line 1298, in _send_request
    self.endheaders(body, encode_chunked=encode_chunked)
  File "/home/katebrich/anaconda3/lib/python3.7/http/client.py", line 1247, in endheaders
    self._send_output(message_body, encode_chunked=encode_chunked)
  File "/home/katebrich/anaconda3/lib/python3.7/http/client.py", line 1026, in _send_output
    self.send(msg)
  File "/home/katebrich/anaconda3/lib/python3.7/http/client.py", line 966, in send
    self.connect()
  File "/home/katebrich/anaconda3/lib/python3.7/http/client.py", line 1422, in connect
    server_hostname=server_hostname)
  File "/home/katebrich/anaconda3/lib/python3.7/ssl.py", line 423, in wrap_socket
    session=session
  File "/home/katebrich/anaconda3/lib/python3.7/ssl.py", line 870, in _create
    self.do_handshake()
  File "/home/katebrich/anaconda3/lib/python3.7/ssl.py", line 1139, in do_handshake
    self._sslobj.do_handshake()
ssl.SSLZeroReturnError: TLS/SSL connection has been closed (EOF) (_ssl.c:1076)

During handling of the above exception, another exception occurred:

Traceback (most recent call last):
  File "./pythonScripts/compute_feature.py", line 19, in __compute_feature
    feat_vals = get_feature(name_of_feature, input_dir, pdb_id, chain_id)
  File "/home/katebrich/Documents/diplomka/GitHub/pythonScripts/features.py", line 15, in get_feature
    return get_pdbkb_conservation(data_dir, pdb_id, chain_id)
  File "/home/katebrich/Documents/diplomka/GitHub/pythonScripts/features.py", line 200, in get_pdbkb_conservation
    response = restAPI_get_json(url)
  File "/home/katebrich/Documents/diplomka/GitHub/pythonScripts/helper.py", line 47, in restAPI_get_json
    return json.loads(restAPI_get(url))
  File "/home/katebrich/Documents/diplomka/GitHub/pythonScripts/helper.py", line 41, in restAPI_get
    with urllib.request.urlopen(req) as f:
  File "/home/katebrich/anaconda3/lib/python3.7/urllib/request.py", line 222, in urlopen
    return opener.open(url, data, timeout)
  File "/home/katebrich/anaconda3/lib/python3.7/urllib/request.py", line 525, in open
    response = self._open(req, data)
  File "/home/katebrich/anaconda3/lib/python3.7/urllib/request.py", line 543, in _open
    '_open', req)
  File "/home/katebrich/anaconda3/lib/python3.7/urllib/request.py", line 503, in _call_chain
    result = func(*args)
  File "/home/katebrich/anaconda3/lib/python3.7/urllib/request.py", line 1362, in https_open
    context=self._context, check_hostname=self._check_hostname)
  File "/home/katebrich/anaconda3/lib/python3.7/urllib/request.py", line 1321, in do_open
    raise URLError(err)
urllib.error.URLError: <urlopen error TLS/SSL connection has been closed (EOF) (_ssl.c:1076)>
2020-08-21 15:22:41,664 [ERROR] compute_feature.py(line 36) 169/250: 1lii A NOT PROCESSED !
2020-08-21 15:24:41,356 [WARNING] compute_feature.py(line 102) Computing feature pdbkb_conservation finished: Some structures were not processed successfully: 
 1rqj A
1lii A
2020-08-21 15:24:41,596 [INFO] compute_feature.py(line 81) Computing feature pdbkb_conservation started...
2020-08-21 15:30:30,127 [ERROR] compute_feature.py(line 28) Error while processing 2q6v A: HTTP Error 500: Internal Server Error
Traceback (most recent call last):
  File "./pythonScripts/compute_feature.py", line 19, in __compute_feature
    feat_vals = get_feature(name_of_feature, input_dir, pdb_id, chain_id)
  File "/home/katebrich/Documents/diplomka/GitHub/pythonScripts/features.py", line 15, in get_feature
    return get_pdbkb_conservation(data_dir, pdb_id, chain_id)
  File "/home/katebrich/Documents/diplomka/GitHub/pythonScripts/features.py", line 200, in get_pdbkb_conservation
    response = restAPI_get_json(url)
  File "/home/katebrich/Documents/diplomka/GitHub/pythonScripts/helper.py", line 47, in restAPI_get_json
    return json.loads(restAPI_get(url))
  File "/home/katebrich/Documents/diplomka/GitHub/pythonScripts/helper.py", line 41, in restAPI_get
    with urllib.request.urlopen(req) as f:
  File "/home/katebrich/anaconda3/lib/python3.7/urllib/request.py", line 222, in urlopen
    return opener.open(url, data, timeout)
  File "/home/katebrich/anaconda3/lib/python3.7/urllib/request.py", line 531, in open
    response = meth(req, response)
  File "/home/katebrich/anaconda3/lib/python3.7/urllib/request.py", line 641, in http_response
    'http', request, response, code, msg, hdrs)
  File "/home/katebrich/anaconda3/lib/python3.7/urllib/request.py", line 569, in error
    return self._call_chain(*args)
  File "/home/katebrich/anaconda3/lib/python3.7/urllib/request.py", line 503, in _call_chain
    result = func(*args)
  File "/home/katebrich/anaconda3/lib/python3.7/urllib/request.py", line 649, in http_error_default
    raise HTTPError(req.full_url, code, msg, hdrs, fp)
urllib.error.HTTPError: HTTP Error 500: Internal Server Error
2020-08-21 15:30:30,131 [ERROR] compute_feature.py(line 36) 273/418: 2q6v A NOT PROCESSED !
2020-08-21 15:30:37,811 [ERROR] compute_feature.py(line 28) Error while processing 2gfx A: <urlopen error TLS/SSL connection has been closed (EOF) (_ssl.c:1076)>
Traceback (most recent call last):
  File "/home/katebrich/anaconda3/lib/python3.7/urllib/request.py", line 1319, in do_open
    encode_chunked=req.has_header('Transfer-encoding'))
  File "/home/katebrich/anaconda3/lib/python3.7/http/client.py", line 1252, in request
    self._send_request(method, url, body, headers, encode_chunked)
  File "/home/katebrich/anaconda3/lib/python3.7/http/client.py", line 1298, in _send_request
    self.endheaders(body, encode_chunked=encode_chunked)
  File "/home/katebrich/anaconda3/lib/python3.7/http/client.py", line 1247, in endheaders
    self._send_output(message_body, encode_chunked=encode_chunked)
  File "/home/katebrich/anaconda3/lib/python3.7/http/client.py", line 1026, in _send_output
    self.send(msg)
  File "/home/katebrich/anaconda3/lib/python3.7/http/client.py", line 966, in send
    self.connect()
  File "/home/katebrich/anaconda3/lib/python3.7/http/client.py", line 1422, in connect
    server_hostname=server_hostname)
  File "/home/katebrich/anaconda3/lib/python3.7/ssl.py", line 423, in wrap_socket
    session=session
  File "/home/katebrich/anaconda3/lib/python3.7/ssl.py", line 870, in _create
    self.do_handshake()
  File "/home/katebrich/anaconda3/lib/python3.7/ssl.py", line 1139, in do_handshake
    self._sslobj.do_handshake()
ssl.SSLZeroReturnError: TLS/SSL connection has been closed (EOF) (_ssl.c:1076)

During handling of the above exception, another exception occurred:

Traceback (most recent call last):
  File "./pythonScripts/compute_feature.py", line 19, in __compute_feature
    feat_vals = get_feature(name_of_feature, input_dir, pdb_id, chain_id)
  File "/home/katebrich/Documents/diplomka/GitHub/pythonScripts/features.py", line 15, in get_feature
    return get_pdbkb_conservation(data_dir, pdb_id, chain_id)
  File "/home/katebrich/Documents/diplomka/GitHub/pythonScripts/features.py", line 191, in get_pdbkb_conservation
    entities = get_uniprot_entity(pdb_id, chain_id)
  File "/home/katebrich/Documents/diplomka/GitHub/pythonScripts/helper.py", line 12, in get_uniprot_entity
    parsedResponse = restAPI_get_json(url)
  File "/home/katebrich/Documents/diplomka/GitHub/pythonScripts/helper.py", line 47, in restAPI_get_json
    return json.loads(restAPI_get(url))
  File "/home/katebrich/Documents/diplomka/GitHub/pythonScripts/helper.py", line 41, in restAPI_get
    with urllib.request.urlopen(req) as f:
  File "/home/katebrich/anaconda3/lib/python3.7/urllib/request.py", line 222, in urlopen
    return opener.open(url, data, timeout)
  File "/home/katebrich/anaconda3/lib/python3.7/urllib/request.py", line 525, in open
    response = self._open(req, data)
  File "/home/katebrich/anaconda3/lib/python3.7/urllib/request.py", line 543, in _open
    '_open', req)
  File "/home/katebrich/anaconda3/lib/python3.7/urllib/request.py", line 503, in _call_chain
    result = func(*args)
  File "/home/katebrich/anaconda3/lib/python3.7/urllib/request.py", line 1362, in https_open
    context=self._context, check_hostname=self._check_hostname)
  File "/home/katebrich/anaconda3/lib/python3.7/urllib/request.py", line 1321, in do_open
    raise URLError(err)
urllib.error.URLError: <urlopen error TLS/SSL connection has been closed (EOF) (_ssl.c:1076)>
2020-08-21 15:30:37,814 [ERROR] compute_feature.py(line 36) 280/418: 2gfx A NOT PROCESSED !
2020-08-21 15:31:48,874 [ERROR] compute_feature.py(line 28) Error while processing 3dzl B: HTTP Error 500: Internal Server Error
Traceback (most recent call last):
  File "./pythonScripts/compute_feature.py", line 19, in __compute_feature
    feat_vals = get_feature(name_of_feature, input_dir, pdb_id, chain_id)
  File "/home/katebrich/Documents/diplomka/GitHub/pythonScripts/features.py", line 15, in get_feature
    return get_pdbkb_conservation(data_dir, pdb_id, chain_id)
  File "/home/katebrich/Documents/diplomka/GitHub/pythonScripts/features.py", line 200, in get_pdbkb_conservation
    response = restAPI_get_json(url)
  File "/home/katebrich/Documents/diplomka/GitHub/pythonScripts/helper.py", line 47, in restAPI_get_json
    return json.loads(restAPI_get(url))
  File "/home/katebrich/Documents/diplomka/GitHub/pythonScripts/helper.py", line 41, in restAPI_get
    with urllib.request.urlopen(req) as f:
  File "/home/katebrich/anaconda3/lib/python3.7/urllib/request.py", line 222, in urlopen
    return opener.open(url, data, timeout)
  File "/home/katebrich/anaconda3/lib/python3.7/urllib/request.py", line 531, in open
    response = meth(req, response)
  File "/home/katebrich/anaconda3/lib/python3.7/urllib/request.py", line 641, in http_response
    'http', request, response, code, msg, hdrs)
  File "/home/katebrich/anaconda3/lib/python3.7/urllib/request.py", line 569, in error
    return self._call_chain(*args)
  File "/home/katebrich/anaconda3/lib/python3.7/urllib/request.py", line 503, in _call_chain
    result = func(*args)
  File "/home/katebrich/anaconda3/lib/python3.7/urllib/request.py", line 649, in http_error_default
    raise HTTPError(req.full_url, code, msg, hdrs, fp)
urllib.error.HTTPError: HTTP Error 500: Internal Server Error
2020-08-21 15:31:48,877 [ERROR] compute_feature.py(line 36) 338/418: 3dzl B NOT PROCESSED !
2020-08-21 15:34:08,965 [WARNING] compute_feature.py(line 102) Computing feature pdbkb_conservation finished: Some structures were not processed successfully: 
 2q6v A
2gfx A
3dzl B
2020-08-21 15:34:09,500 [INFO] create_p2rank_custom_feature_files.py(line 128) Creating p2rank custom feature files started...
2020-08-21 15:35:21,103 [ERROR] create_p2rank_custom_feature_files.py(line 73) Error while processing 1rqj A: /home/katebrich/Documents/diplomka/datasets/chen11_coach420/chen11/features/pdbkb_conservation/1rqjA.txt not found.
Traceback (most recent call last):
  File "./pythonScripts/create_p2rank_custom_feature_files.py", line 37, in create_file
    feature_vals.append(read_feature_vals(feature, input_dir, pdb_id, chain_id))  # todo
  File "./pythonScripts/create_p2rank_custom_feature_files.py", line 21, in read_feature_vals
    feature_vals = np.genfromtxt(path, delimiter=' ')
  File "/home/katebrich/anaconda3/lib/python3.7/site-packages/numpy/lib/npyio.py", line 1772, in genfromtxt
    fid = np.lib._datasource.open(fname, 'rt', encoding=encoding)
  File "/home/katebrich/anaconda3/lib/python3.7/site-packages/numpy/lib/_datasource.py", line 269, in open
    return ds.open(path, mode, encoding=encoding, newline=newline)
  File "/home/katebrich/anaconda3/lib/python3.7/site-packages/numpy/lib/_datasource.py", line 623, in open
    raise IOError("%s not found." % path)
OSError: /home/katebrich/Documents/diplomka/datasets/chen11_coach420/chen11/features/pdbkb_conservation/1rqjA.txt not found.
2020-08-21 15:35:21,127 [ERROR] create_p2rank_custom_feature_files.py(line 81) 48/250: 1rqj A NOT PROCESSED !
2020-08-21 15:38:22,233 [ERROR] create_p2rank_custom_feature_files.py(line 73) Error while processing 1lii A: /home/katebrich/Documents/diplomka/datasets/chen11_coach420/chen11/features/pdbkb_conservation/1liiA.txt not found.
Traceback (most recent call last):
  File "./pythonScripts/create_p2rank_custom_feature_files.py", line 37, in create_file
    feature_vals.append(read_feature_vals(feature, input_dir, pdb_id, chain_id))  # todo
  File "./pythonScripts/create_p2rank_custom_feature_files.py", line 21, in read_feature_vals
    feature_vals = np.genfromtxt(path, delimiter=' ')
  File "/home/katebrich/anaconda3/lib/python3.7/site-packages/numpy/lib/npyio.py", line 1772, in genfromtxt
    fid = np.lib._datasource.open(fname, 'rt', encoding=encoding)
  File "/home/katebrich/anaconda3/lib/python3.7/site-packages/numpy/lib/_datasource.py", line 269, in open
    return ds.open(path, mode, encoding=encoding, newline=newline)
  File "/home/katebrich/anaconda3/lib/python3.7/site-packages/numpy/lib/_datasource.py", line 623, in open
    raise IOError("%s not found." % path)
OSError: /home/katebrich/Documents/diplomka/datasets/chen11_coach420/chen11/features/pdbkb_conservation/1liiA.txt not found.
2020-08-21 15:38:22,238 [ERROR] create_p2rank_custom_feature_files.py(line 81) 166/250: 1lii A NOT PROCESSED !
2020-08-21 15:40:18,834 [WARNING] create_p2rank_custom_feature_files.py(line 153) Creating p2rank custom feature files finished: Some structures were not processed successfully: 
 1rqj A
1lii A
2020-08-21 15:40:19,327 [INFO] create_p2rank_custom_feature_files.py(line 128) Creating p2rank custom feature files started...
