2020-11-13 21:32:24,567 [INFO] DatasetDownloader.py(line 50) Downloading structures to /home/katebrich/Documents/diplomka/P2Rank/datasets/11_13/test started...
2020-11-13 21:32:24,839 [DEBUG] DatasetDownloader.py(line 110) Error while downloading 1kae X: 1kae X: Wrong number of entity IDs! 0
Traceback (most recent call last):
  File "/home/katebrich/Documents/diplomka/GitHub/pythonScripts/DatasetDownloader.py", line 103, in download_structure
    self.get_FASTA(self.output_FASTA, pdb_id, chain_ids)
  File "/home/katebrich/Documents/diplomka/GitHub/pythonScripts/DatasetDownloader.py", line 84, in get_FASTA
    entity_id = get_entity_id(pdb_id, chain_id)
  File "/home/katebrich/Documents/diplomka/GitHub/pythonScripts/helper.py", line 154, in get_entity_id
    raise ValueError(f"{pdb_id} {chain_id}: Wrong number of entity IDs! {len(entity_ids)}") #todo jen debug
ValueError: 1kae X: Wrong number of entity IDs! 0
2020-11-13 21:32:24,842 [ERROR] DatasetDownloader.py(line 120) 1/13: 1kae X NOT PROCESSED ! See log for more details.
2020-11-13 21:32:24,864 [DEBUG] DatasetDownloader.py(line 110) Error while downloading XXXX X: HTTP Error 404: Not Found
Traceback (most recent call last):
  File "/home/katebrich/Documents/diplomka/GitHub/pythonScripts/DatasetDownloader.py", line 103, in download_structure
    self.get_FASTA(self.output_FASTA, pdb_id, chain_ids)
  File "/home/katebrich/Documents/diplomka/GitHub/pythonScripts/DatasetDownloader.py", line 84, in get_FASTA
    entity_id = get_entity_id(pdb_id, chain_id)
  File "/home/katebrich/Documents/diplomka/GitHub/pythonScripts/helper.py", line 146, in get_entity_id
    response = restAPI_get_json(url)
  File "/home/katebrich/Documents/diplomka/GitHub/pythonScripts/helper.py", line 93, in restAPI_get_json
    return json.loads(restAPI_get(url))
  File "/home/katebrich/Documents/diplomka/GitHub/pythonScripts/helper.py", line 87, in restAPI_get
    with urllib.request.urlopen(req) as f:
  File "/home/katebrich/anaconda3/envs/diplomka_2/lib/python3.8/urllib/request.py", line 222, in urlopen
    return opener.open(url, data, timeout)
  File "/home/katebrich/anaconda3/envs/diplomka_2/lib/python3.8/urllib/request.py", line 531, in open
    response = meth(req, response)
  File "/home/katebrich/anaconda3/envs/diplomka_2/lib/python3.8/urllib/request.py", line 640, in http_response
    response = self.parent.error(
  File "/home/katebrich/anaconda3/envs/diplomka_2/lib/python3.8/urllib/request.py", line 569, in error
    return self._call_chain(*args)
  File "/home/katebrich/anaconda3/envs/diplomka_2/lib/python3.8/urllib/request.py", line 502, in _call_chain
    result = func(*args)
  File "/home/katebrich/anaconda3/envs/diplomka_2/lib/python3.8/urllib/request.py", line 649, in http_error_default
    raise HTTPError(req.full_url, code, msg, hdrs, fp)
urllib.error.HTTPError: HTTP Error 404: Not Found
2020-11-13 21:32:24,868 [ERROR] DatasetDownloader.py(line 120) 2/13: XXXX X NOT PROCESSED ! See log for more details.
2020-11-13 21:32:30,803 [WARNING] DatasetDownloader.py(line 64) Downloading structures finished in 7s. 2/13 structures were not downloaded successfully: 
XXXX X
1kae X
2020-11-13 21:32:30,812 [INFO] MappingsComputer.py(line 31) Creating mapping cache started...
2020-11-13 21:32:31,066 [DEBUG] MappingsComputer.py(line 63) Error while processing 1kae X: HTTP Error 404: Not Found
2020-11-13 21:32:31,068 [ERROR] MappingsComputer.py(line 71) 1/13: 1kae X NOT PROCESSED ! See log for more details.
2020-11-13 21:32:31,082 [DEBUG] MappingsComputer.py(line 63) Error while processing XXXX X: HTTP Error 404: Not Found
2020-11-13 21:32:31,083 [ERROR] MappingsComputer.py(line 71) 2/13: XXXX X NOT PROCESSED ! See log for more details.
2020-11-13 21:32:32,759 [WARNING] MappingsComputer.py(line 46) Creating mapping cache finished in 2s. 2/13 structures were not processed successfully: 
XXXX X
1kae X
2020-11-13 21:32:32,772 [INFO] LigandBindingSitesComputer.py(line 54) Computing ligand binding sites started...
2020-11-13 21:32:32,798 [DEBUG] LigandBindingSitesComputer.py(line 87) Error while processing XXXX X: /home/katebrich/Documents/diplomka/P2Rank/datasets/11_13/test/mappings/XXXXX.txt not found.
Traceback (most recent call last):
  File "/home/katebrich/Documents/diplomka/GitHub/pythonScripts/LigandBindingSitesComputer.py", line 79, in get_ligand_binding_site
    lbs = self.compute_ligand_binding_sites(structure, pdb_path)
  File "/home/katebrich/Documents/diplomka/GitHub/pythonScripts/LigandBindingSitesComputer.py", line 108, in compute_ligand_binding_sites
    mappings = dict(res_mappings_author_to_pdbe(pdb_id, chain_id, get_mappings_path2(self.mappings_dir, pdb_id, chain_id)))
  File "/home/katebrich/Documents/diplomka/GitHub/pythonScripts/helper.py", line 160, in res_mappings_author_to_pdbe
    mappings = np.genfromtxt(cache_file, delimiter=' ', dtype='str')
  File "/home/katebrich/.local/lib/python3.8/site-packages/numpy/lib/npyio.py", line 1772, in genfromtxt
    fid = np.lib._datasource.open(fname, 'rt', encoding=encoding)
  File "/home/katebrich/.local/lib/python3.8/site-packages/numpy/lib/_datasource.py", line 269, in open
    return ds.open(path, mode, encoding=encoding, newline=newline)
  File "/home/katebrich/.local/lib/python3.8/site-packages/numpy/lib/_datasource.py", line 623, in open
    raise IOError("%s not found." % path)
OSError: /home/katebrich/Documents/diplomka/P2Rank/datasets/11_13/test/mappings/XXXXX.txt not found.
2020-11-13 21:32:32,798 [DEBUG] LigandBindingSitesComputer.py(line 87) Error while processing 1kae X: /home/katebrich/Documents/diplomka/P2Rank/datasets/11_13/test/mappings/1kaeX.txt not found.
Traceback (most recent call last):
  File "/home/katebrich/Documents/diplomka/GitHub/pythonScripts/LigandBindingSitesComputer.py", line 79, in get_ligand_binding_site
    lbs = self.compute_ligand_binding_sites(structure, pdb_path)
  File "/home/katebrich/Documents/diplomka/GitHub/pythonScripts/LigandBindingSitesComputer.py", line 108, in compute_ligand_binding_sites
    mappings = dict(res_mappings_author_to_pdbe(pdb_id, chain_id, get_mappings_path2(self.mappings_dir, pdb_id, chain_id)))
  File "/home/katebrich/Documents/diplomka/GitHub/pythonScripts/helper.py", line 160, in res_mappings_author_to_pdbe
    mappings = np.genfromtxt(cache_file, delimiter=' ', dtype='str')
  File "/home/katebrich/.local/lib/python3.8/site-packages/numpy/lib/npyio.py", line 1772, in genfromtxt
    fid = np.lib._datasource.open(fname, 'rt', encoding=encoding)
  File "/home/katebrich/.local/lib/python3.8/site-packages/numpy/lib/_datasource.py", line 269, in open
    return ds.open(path, mode, encoding=encoding, newline=newline)
  File "/home/katebrich/.local/lib/python3.8/site-packages/numpy/lib/_datasource.py", line 623, in open
    raise IOError("%s not found." % path)
OSError: /home/katebrich/Documents/diplomka/P2Rank/datasets/11_13/test/mappings/1kaeX.txt not found.
2020-11-13 21:32:32,812 [ERROR] LigandBindingSitesComputer.py(line 95) 1/13: XXXX X NOT PROCESSED ! See log for more details.
2020-11-13 21:32:32,812 [ERROR] LigandBindingSitesComputer.py(line 95) 2/13: 1kae X NOT PROCESSED ! See log for more details.
2020-11-13 21:32:35,859 [WARNING] LigandBindingSitesComputer.py(line 69) Computing ligand binding sites finished in 4s. 2/13 structures were not processed successfully: 
XXXX X
1kae X
